<?xml version="1.0" ?>
<!-- Generated using onshape-to-robot -->
<!-- Onshape https://cad.onshape.com/documents/fb645318a27646d1d8840be6/w/d1cae8805fb652b4d1614997/e/64ce30b04dcb58987e9083b2 -->
<mujoco model="mjcf">
  <compiler angle="radian" meshdir="assets" autolimits="true"/>
  <default>
    <default class="mjcf">
      <joint frictionloss="0.1" armature="0.005"/>
      <position kp="50" dampratio="1"/>
      <default class="visual">
        <geom type="mesh" contype="0" conaffinity="0" group="2"/>
      </default>
      <default class="collision">
        <geom group="3" type="capsule" contype="1" conaffinity="1"/>
      </default>
    </default>
  </default>
  <worldbody>
    <!-- Link torso_subassembly -->
    <body name="torso_subassembly" pos="0 0 0.72" quat="1 0 0 0" childclass="mjcf">
      <freejoint name="torso_subassembly_freejoint"/>
      <inertial pos="-0.000697254 4.08729e-07 0.0361785" mass="1.37455" fullinertia="0.0195228 0.00129235 0.0197822 -3.0234e-10 1.40229e-06 1.22091e-10"/>
      <!-- Part rs00 -->
      <!-- Part torso22 -->
      <geom type="mesh" class="visual" pos="-0.000263039 0.233572 -0.0901625" quat="1.11022e-16 0 0.990051 -0.140711" mesh="torso22" material="torso22_material"/>
      <!-- Part hex_socket_head_cap_screw_m4x0_70_x_20__832e47d784177ea3f1dabbaab534416e -->
      <!-- Part rs00_2 -->
      <!-- Part hex_socket_head_cap_screw_m4x0_70_x_20__832e47d784177ea3f1dabbaab534416e_2 -->
      <!-- Part hex_socket_head_cap_screw_m3x0_50_x_8__d566997e1880d7fd3377c5b0ee12206c -->
      <!-- Part hex_socket_head_cap_screw_m3x0_50_x_8__d566997e1880d7fd3377c5b0ee12206c_2 -->
      <!-- Part bearing_35_72_17 -->
      <geom type="mesh" class="visual" pos="-0.000887454 -0.130401 0.0222352" quat="0.0013181 -0.00114402 -0.655472 -0.755218" mesh="bearing_35_72_17" material="bearing_35_72_17_material"/>
      <!-- Part hex_socket_head_cap_screw_m4x0_70_x_20__832e47d784177ea3f1dabbaab534416e_3 -->
      <!-- Part hex_socket_head_cap_screw_m4x0_70_x_20__832e47d784177ea3f1dabbaab534416e_4 -->
      <!-- Part hex_socket_head_cap_screw_m4x0_70_x_20__832e47d784177ea3f1dabbaab534416e_5 -->
      <!-- Part robstrideo0 -->
      <geom type="mesh" class="visual" pos="0.672086 -0.147255 0.0629195" quat="0.0013181 -0.00114402 -0.655472 -0.755218" mesh="robstrideo0" material="robstrideo0_material"/>
      <!-- Part hex_socket_head_cap_screw_m3x0_50_x_8__d566997e1880d7fd3377c5b0ee12206c_3 -->
      <!-- Part hex_socket_head_cap_screw_m4x0_70_x_20__832e47d784177ea3f1dabbaab534416e_6 -->
      <!-- Part hex_socket_head_cap_screw_m3x0_50_x_8__d566997e1880d7fd3377c5b0ee12206c_4 -->
      <!-- Part hex_socket_head_cap_screw_m4x0_70_x_20__832e47d784177ea3f1dabbaab534416e_7 -->
      <!-- Part hex_socket_head_cap_screw_m4x0_70_x_20__832e47d784177ea3f1dabbaab534416e_8 -->
      <!-- Part hex_socket_head_cap_screw_m3x0_50_x_8__d566997e1880d7fd3377c5b0ee12206c_5 -->
      <!-- Part hex_socket_head_cap_screw_m4x0_70_x_20__832e47d784177ea3f1dabbaab534416e_9 -->
      <!-- Part hex_socket_head_cap_screw_m3x0_50_x_8__d566997e1880d7fd3377c5b0ee12206c_6 -->
      <!-- Part robstrideo0_2 -->
      <geom type="mesh" class="visual" pos="0.672086 0.12555 0.0660044" quat="0.00114402 -0.0013181 -0.755218 -0.655472" mesh="robstrideo0" material="robstrideo0_material"/>
      <!-- Part hex_socket_head_cap_screw_m3x0_50_x_8__d566997e1880d7fd3377c5b0ee12206c_7 -->
      <!-- Part hex_socket_head_cap_screw_m3x0_50_x_8__d566997e1880d7fd3377c5b0ee12206c_8 -->
      <!-- Part hex_socket_head_cap_screw_m4x0_70_x_20__832e47d784177ea3f1dabbaab534416e_10 -->
      <!-- Part torso12 -->
      <geom type="mesh" class="visual" pos="-0.000263039 4.05842e-07 -0.056966" quat="2.22045e-16 -0 -1 1.38778e-17" mesh="torso12" material="torso12_material"/>
      <!-- Part hex_socket_head_cap_screw_m4x0_70_x_20__832e47d784177ea3f1dabbaab534416e_11 -->
      <!-- Part hex_socket_head_cap_screw_m4x0_70_x_20__832e47d784177ea3f1dabbaab534416e_12 -->
      <!-- Part torso22_2 -->
      <geom type="mesh" class="visual" pos="-0.000263039 4.05842e-07 -0.056966" quat="1.11022e-16 0 1 -1.11022e-16" mesh="torso22" material="torso22_material"/>
      <!-- Part hex_socket_head_cap_screw_m4x0_70_x_20__832e47d784177ea3f1dabbaab534416e_13 -->
      <!-- Part bearing_35_72_17_2 -->
      <geom type="mesh" class="visual" pos="-0.000887454 0.130402 0.0222352" quat="0.00114402 -0.0013181 -0.755218 -0.655472" mesh="bearing_35_72_17" material="bearing_35_72_17_material"/>
      <!-- Part hex_socket_head_cap_screw_m3x0_50_x_8__d566997e1880d7fd3377c5b0ee12206c_9 -->
      <!-- Part hex_socket_head_cap_screw_m3x0_50_x_8__d566997e1880d7fd3377c5b0ee12206c_10 -->
      <!-- Part hex_socket_head_cap_screw_m3x0_50_x_8__d566997e1880d7fd3377c5b0ee12206c_11 -->
      <!-- Part hex_socket_head_cap_screw_m4x0_70_x_20__832e47d784177ea3f1dabbaab534416e_14 -->
      <!-- Part xt_30_2x2_f -->
      <geom type="mesh" class="visual" pos="-3.97731e-05 -0.105809 0.0903709" quat="0.464297 0.534952 -0.533088 0.46268" mesh="xt_30_2x2_f" material="xt_30_2x2_f_material"/>
      <!-- Part hex_socket_head_cap_screw_m4x0_70_x_20__832e47d784177ea3f1dabbaab534416e_15 -->
      <!-- Part hex_socket_head_cap_screw_m4x0_70_x_20__832e47d784177ea3f1dabbaab534416e_16 -->
      <!-- Part hex_socket_head_cap_screw_m3x0_50_x_8__d566997e1880d7fd3377c5b0ee12206c_12 -->
      <!-- Frame imu -->
      <site group="3" name="imu" pos="2.52201e-19 -1.6263e-19 -2.60209e-18" quat="1 0 1.11022e-16 0"/>
      <!-- Link hipx_subassembly -->
      <body name="hipx_subassembly" pos="-0.000819037 -0.133159 0.04164" quat="0.821908 0.0571233 0.0414078 -0.565234">
        <!-- Joint from torso_subassembly to hipx_subassembly -->
        <joint axis="0 0 1" name="hipz_right" type="hinge"/>
        <inertial pos="-0.0179437 -0.0274254 -0.0837243" mass="0.794013" fullinertia="0.00093782 0.000903422 0.00100397 -4.40032e-05 -0.00011053 -0.000168643"/>
        <!-- Part rs02 -->
        <!-- Part hex_socket_head_cap_screw_m4x0_70_x_40__14321d45d56569246e7feb4574a6bae6 -->
        <!-- Part hex_socket_head_cap_screw_m3x0_50_x_8__d566997e1880d7fd3377c5b0ee12206c_13 -->
        <!-- Part hex_socket_head_cap_screw_m3x0_50_x_8__d566997e1880d7fd3377c5b0ee12206c_14 -->
        <!-- Part hex_socket_head_cap_screw_m4x0_70_x_40__14321d45d56569246e7feb4574a6bae6_2 -->
        <!-- Part hex_socket_head_cap_screw_m3x0_50_x_8__d566997e1880d7fd3377c5b0ee12206c_15 -->
        <!-- Part xt_30_2x2_f_2 -->
        <geom type="mesh" class="visual" pos="-0.0280156 -0.000591536 -0.0506633" quat="0.372266 0.524562 -0.593709 0.48349" mesh="xt_30_2x2_f" material="xt_30_2x2_f_material"/>
        <!-- Part hex_socket_head_cap_screw_m3x0_50_x_8__d566997e1880d7fd3377c5b0ee12206c_16 -->
        <!-- Part hex_socket_head_cap_screw_m4x0_70_x_40__14321d45d56569246e7feb4574a6bae6_3 -->
        <!-- Part hex_socket_head_cap_screw_m4x0_70_x_40__14321d45d56569246e7feb4574a6bae6_4 -->
        <!-- Part hex_socket_head_cap_screw_m3x0_50_x_8__d566997e1880d7fd3377c5b0ee12206c_17 -->
        <!-- Part hipz12 -->
        <geom type="mesh" class="visual" pos="-1.38778e-17 0 -0.1" quat="0 1 0 0" mesh="hipz12" material="hipz12_material"/>
        <!-- Part hex_socket_head_cap_screw_m4x0_70_x_40__14321d45d56569246e7feb4574a6bae6_5 -->
        <!-- Part hex_socket_head_cap_screw_m3x0_50_x_8__d566997e1880d7fd3377c5b0ee12206c_18 -->
        <!-- Part hex_socket_head_cap_screw_m3x0_50_x_8__d566997e1880d7fd3377c5b0ee12206c_19 -->
        <!-- Part robstride02 -->
        <geom type="mesh" class="visual" pos="-0.575896 0.0494047 -0.172196" quat="0.792908 -0.60316 -0.0524169 -0.0689068" mesh="robstride02" material="robstride02_material"/>
        <!-- Part hex_socket_head_cap_screw_m4x0_70_x_40__14321d45d56569246e7feb4574a6bae6_6 -->
        <!-- Part hex_socket_head_cap_screw_m3x0_50_x_8__d566997e1880d7fd3377c5b0ee12206c_20 -->
        <!-- Part hex_socket_head_cap_screw_m4x0_70_x_40__14321d45d56569246e7feb4574a6bae6_7 -->
        <!-- Part hex_socket_head_cap_screw_m4x0_70_x_40__14321d45d56569246e7feb4574a6bae6_8 -->
        <!-- Part hex_socket_head_cap_screw_m3x0_50_x_8__d566997e1880d7fd3377c5b0ee12206c_21 -->
        <!-- Part bearing_35_72_17_3 -->
        <geom type="mesh" class="visual" pos="-0.01759 -0.0267968 -0.104484" quat="0.60316 0.792908 -0.0689068 0.0524169" mesh="bearing_35_72_17" material="bearing_35_72_17_material"/>
        <!-- Part hex_socket_head_cap_screw_m3x0_50_x_8__d566997e1880d7fd3377c5b0ee12206c_22 -->
        <!-- Part hex_socket_head_cap_screw_m3x0_50_x_8__d566997e1880d7fd3377c5b0ee12206c_23 -->
        <!-- Part hex_socket_head_cap_screw_m4x0_70_x_40__14321d45d56569246e7feb4574a6bae6_9 -->
        <!-- Part hex_socket_head_cap_screw_m3x0_50_x_8__d566997e1880d7fd3377c5b0ee12206c_24 -->
        <!-- Part hipz22 -->
        <geom type="mesh" class="visual" pos="-2.77556e-17 2.08167e-17 -0.1" quat="2.2923e-17 1 2.09241e-16 -5.7946e-17" mesh="hipz22" material="hipz22_material"/>
        <!-- Part hex_socket_head_cap_screw_m3x0_50_x_8__d566997e1880d7fd3377c5b0ee12206c_25 -->
        <!-- Part hex_socket_head_cap_screw_m3x0_50_x_8__d566997e1880d7fd3377c5b0ee12206c_26 -->
        <!-- Part hex_socket_head_cap_screw_m3x0_50_x_8__d566997e1880d7fd3377c5b0ee12206c_27 -->
        <!-- Part hex_socket_head_cap_screw_m4x0_70_x_40__14321d45d56569246e7feb4574a6bae6_10 -->
        <!-- Link hipy_subassembly -->
        <body name="hipy_subassembly" pos="-0.01897 -0.0289 -0.09689" quat="0.388859 0.13275 0.0879729 -0.907429">
          <!-- Joint from hipx_subassembly to hipy_subassembly -->
          <joint axis="0 0 1" name="hipx_right" type="hinge"/>
          <inertial pos="0.00476547 -0.00266343 -0.0607297" mass="0.241618" fullinertia="0.000504044 0.000455767 0.000428966 2.43362e-05 7.84949e-06 -3.61499e-05"/>
          <!-- Part hex_socket_head_cap_screw_m4x0_70_x_20__832e47d784177ea3f1dabbaab534416e_17 -->
          <!-- Part hipxy -->
          <geom type="mesh" class="visual" pos="-8.67362e-19 -1.38778e-17 6.93889e-18" quat="1 -0 -2.22045e-16 8.32667e-17" mesh="hipxy" material="hipxy_material"/>
          <!-- Part hex_socket_head_cap_screw_m4x0_70_x_20__832e47d784177ea3f1dabbaab534416e_18 -->
          <!-- Part hex_socket_head_cap_screw_m4x0_70_x_20__832e47d784177ea3f1dabbaab534416e_19 -->
          <!-- Part hex_socket_head_cap_screw_m4x0_70_x_12__c825518ee8edf1afced0eee1b019b750 -->
          <!-- Part hex_socket_head_cap_screw_m4x0_70_x_20__832e47d784177ea3f1dabbaab534416e_20 -->
          <!-- Part hex_socket_head_cap_screw_m4x0_70_x_12__c825518ee8edf1afced0eee1b019b750_2 -->
          <!-- Part hex_socket_head_cap_screw_m4x0_70_x_12__c825518ee8edf1afced0eee1b019b750_3 -->
          <!-- Part hex_socket_head_cap_screw_m4x0_70_x_20__832e47d784177ea3f1dabbaab534416e_21 -->
          <!-- Part hex_socket_head_cap_screw_m4x0_70_x_20__832e47d784177ea3f1dabbaab534416e_22 -->
          <!-- Part hex_socket_head_cap_screw_m4x0_70_x_12__c825518ee8edf1afced0eee1b019b750_4 -->
          <!-- Part hex_socket_head_cap_screw_m4x0_70_x_12__c825518ee8edf1afced0eee1b019b750_5 -->
          <!-- Part hex_socket_head_cap_screw_m4x0_70_x_12__c825518ee8edf1afced0eee1b019b750_6 -->
          <!-- Link tigh_subassembly -->
          <body name="tigh_subassembly" pos="0.012638 -0.0276823 -0.112055" quat="0.289457 0.00726416 0.730479 -0.618516">
            <!-- Joint from hipy_subassembly to tigh_subassembly -->
            <joint axis="0 0 1" name="hipy_right" type="hinge"/>
            <inertial pos="0.0501976 0.0785779 -0.0353813" mass="2.5804" fullinertia="0.0174359 0.00865749 0.0236145 -0.0081889 0.000938636 0.00155247"/>
            <!-- Part hex_socket_head_cap_screw_m3x0_50_x_10__9c80fcbba574884e63b580474e1ee150 -->
            <!-- Part hex_socket_head_cap_screw_m2_5x0_45_x_6__ec244025d76f8b83b2775022a2cb3232 -->
            <!-- Part hex_socket_head_cap_screw_m4x0_70_x_8__a416dc2a8d778a4ef6150c0739aa89d1 -->
            <!-- Part hex_socket_head_cap_screw_m2_5x0_45_x_6__ec244025d76f8b83b2775022a2cb3232_2 -->
            <!-- Part hex_socket_head_cap_screw_m4x0_70_x_8__a416dc2a8d778a4ef6150c0739aa89d1_2 -->
            <!-- Part hex_socket_head_cap_screw_m3x0_50_x_10__9c80fcbba574884e63b580474e1ee150_2 -->
            <!-- Part hex_socket_head_cap_screw_m4x0_70_x_16__8d628c0d7a90368385b1c4c7479647eb -->
            <!-- Part hex_socket_head_cap_screw_m4x0_70_x_8__a416dc2a8d778a4ef6150c0739aa89d1_3 -->
            <!-- Part hex_socket_head_cap_screw_m4x0_70_x_16__8d628c0d7a90368385b1c4c7479647eb_2 -->
            <!-- Part hex_socket_head_cap_screw_m4x0_70_x_8__a416dc2a8d778a4ef6150c0739aa89d1_4 -->
            <!-- Part knee_rod22 -->
            <geom type="mesh" class="visual" pos="0.210506 0.184547 -0.0305" quat="0.612372 0.612372 -0.353553 -0.353553" mesh="knee_rod22" material="knee_rod22_material"/>
            <!-- Part hex_socket_head_cap_screw_m4x0_70_x_8__a416dc2a8d778a4ef6150c0739aa89d1_5 -->
            <!-- Part hex_socket_head_cap_screw_m4x0_70_x_16__8d628c0d7a90368385b1c4c7479647eb_3 -->
            <!-- Part hex_socket_head_cap_screw_m4x0_70_x_16__8d628c0d7a90368385b1c4c7479647eb_4 -->
            <!-- Part hex_socket_head_cap_screw_m4x0_70_x_8__a416dc2a8d778a4ef6150c0739aa89d1_6 -->
            <!-- Part bearing_15_21_4 -->
            <geom type="mesh" class="visual" pos="0.117923 0.320381 -0.0185" quat="0.612372 -0.612372 0.353553 -0.353553" mesh="bearing_15_21_4" material="bearing_15_21_4_material"/>
            <!-- Part bearing_15_21_4_2 -->
            <geom type="mesh" class="visual" pos="0.0130854 0.122429 -0.0245" quat="0.707107 -0.707107 7.26086e-14 -1.03318e-13" mesh="bearing_15_21_4" material="bearing_15_21_4_material"/>
            <!-- Part hex_socket_head_cap_screw_m2_5x0_45_x_6__ec244025d76f8b83b2775022a2cb3232_3 -->
            <!-- Part hex_socket_head_cap_screw_m4x0_70_x_8__a416dc2a8d778a4ef6150c0739aa89d1_7 -->
            <!-- Part robstrideo3 -->
            <geom type="mesh" class="visual" pos="-0.437806 0.570998 -0.07" quat="0.683013 -0.683013 0.183013 -0.183013" mesh="robstrideo3" material="robstrideo3_material"/>
            <!-- Part hex_socket_head_cap_screw_m4x0_70_x_16__8d628c0d7a90368385b1c4c7479647eb_5 -->
            <!-- Part bearing_15_21_4_3 -->
            <geom type="mesh" class="visual" pos="2.76862e-15 -1.24067e-14 -0.0635" quat="0.683013 0.683013 -0.183013 -0.183013" mesh="bearing_15_21_4" material="bearing_15_21_4_material"/>
            <!-- Part bearing_15_21_4_4 -->
            <geom type="mesh" class="visual" pos="0.0130854 0.122429 -0.0365" quat="0.707107 0.707107 -1.02918e-13 -7.29873e-14" mesh="bearing_15_21_4" material="bearing_15_21_4_material"/>
            <!-- Part hex_socket_head_cap_screw_m4x0_70_x_40__14321d45d56569246e7feb4574a6bae6_11 -->
            <!-- Part bearing_15_21_4_5 -->
            <geom type="mesh" class="visual" pos="0.117923 0.320381 -0.0425" quat="0.612372 0.612372 -0.353553 -0.353553" mesh="bearing_15_21_4" material="bearing_15_21_4_material"/>
            <!-- Part hex_socket_head_cap_screw_m4x0_70_x_40__14321d45d56569246e7feb4574a6bae6_12 -->
            <!-- Part hex_socket_head_cap_screw_m4x0_70_x_8__a416dc2a8d778a4ef6150c0739aa89d1_8 -->
            <!-- Part hex_socket_head_cap_screw_m2_5x0_45_x_6__ec244025d76f8b83b2775022a2cb3232_4 -->
            <!-- Part hex_socket_head_cap_screw_m2_5x0_45_x_6__ec244025d76f8b83b2775022a2cb3232_5 -->
            <!-- Part hex_socket_head_cap_screw_m4x0_70_x_8__a416dc2a8d778a4ef6150c0739aa89d1_9 -->
            <!-- Part knee_rod12 -->
            <geom type="mesh" class="visual" pos="0.210506 0.184547 -0.0305" quat="0.612372 0.612372 -0.353553 -0.353553" mesh="knee_rod12" material="knee_rod12_material"/>
            <!-- Part hex_socket_head_cap_screw_m4x0_70_x_8__a416dc2a8d778a4ef6150c0739aa89d1_10 -->
            <!-- Part bearing_5_16_5 -->
            <geom type="mesh" class="visual" pos="0.17 0.294449 -0.05" quat="0.683013 -0.683013 0.183013 -0.183013" mesh="bearing_5_16_5" material="bearing_5_16_5_material"/>
            <!-- Part hex_socket_head_cap_screw_m4x0_70_x_8__a416dc2a8d778a4ef6150c0739aa89d1_11 -->
            <!-- Part hex_socket_head_cap_screw_m4x0_70_x_8__a416dc2a8d778a4ef6150c0739aa89d1_12 -->
            <!-- Part hex_socket_head_cap_screw_m4x0_70_x_8__a416dc2a8d778a4ef6150c0739aa89d1_13 -->
            <!-- Part hex_socket_head_cap_screw_m4x0_70_x_40__14321d45d56569246e7feb4574a6bae6_13 -->
            <!-- Part knee_actuation -->
            <geom type="mesh" class="visual" pos="0.058 0.324459 -0.0305" quat="0.707107 0.707107 -1.03029e-13 -7.26047e-14" mesh="knee_actuation" material="knee_actuation_material"/>
            <!-- Part hex_socket_head_cap_screw_m4x0_70_x_16__8d628c0d7a90368385b1c4c7479647eb_6 -->
            <!-- Part hex_socket_head_cap_screw_m3x0_50_x_10__9c80fcbba574884e63b580474e1ee150_3 -->
            <!-- Part hex_socket_head_cap_screw_m4x0_70_x_8__a416dc2a8d778a4ef6150c0739aa89d1_14 -->
            <!-- Part bearing_5_16_5_2 -->
            <geom type="mesh" class="visual" pos="0.17 0.294449 -0.01425" quat="0.683013 -0.683013 0.183013 -0.183013" mesh="bearing_5_16_5" material="bearing_5_16_5_material"/>
            <!-- Part femur_22 -->
            <geom type="mesh" class="visual" pos="0.17 0.294449 -0.0305" quat="0.683013 0.683013 -0.183013 -0.183013" mesh="femur_22" material="femur_22_material"/>
            <!-- Part hex_socket_head_cap_screw_m4x0_70_x_40__14321d45d56569246e7feb4574a6bae6_14 -->
            <!-- Part femur_12 -->
            <geom type="mesh" class="visual" pos="0.17 0.294449 -0.0305" quat="0.683013 0.683013 -0.183013 -0.183013" mesh="femur_12" material="femur_12_material"/>
            <geom name="femur_12_collision" type="capsule" size="0.05 0.18" class="collision" pos="0.17 0.294449 -0.0305" quat="0.683013 0.683013 -0.183013 -0.183013"/>
            <!-- Part hat_femur -->
            <geom type="mesh" class="visual" pos="0.17 0.294449 -0.0305" quat="0.683013 0.683013 -0.183013 -0.183013" mesh="hat_femur" material="hat_femur_material"/>
            <!-- Part part_3 -->
            <geom type="mesh" class="visual" pos="3.44516e-15 -2.18436e-14 -0.0938" quat="0.183013 -0.683013 0.183013 0.683013" mesh="part_3" material="part_3_material"/>
            <!-- Part robstrideo3_2 -->
            <geom type="mesh" class="visual" pos="-0.495806 0.470539 -0.0275" quat="0.683013 -0.683013 0.183013 -0.183013" mesh="robstrideo3" material="robstrideo3_material"/>
            <!-- Part hex_socket_head_cap_screw_m2_5x0_45_x_6__ec244025d76f8b83b2775022a2cb3232_6 -->
            <!-- Part 1_1_31_qt_942_1 -->
            <geom type="mesh" class="visual" pos="4.01762e-15 -5.2458e-15 -0.04" quat="0.5 -4.48959e-14 -9.71445e-14 -0.866025" mesh="1_1_31_qt_942_1" material="1_1_31_qt_942_1_material"/>
            <!-- Part 1_1_06_eb903_538_1 -->
            <geom type="mesh" class="visual" pos="4.73233e-15 -7.21645e-15 -0.0566" quat="0.5 -4.48959e-14 -9.71445e-14 -0.866025" mesh="1_1_06_eb903_538_1" material="1_1_06_eb903_538_1_material"/>
            <!-- Part 1_1_31_qt_942_1_2 -->
            <geom type="mesh" class="visual" pos="0.058 0.100459 -0.0825" quat="0.258819 -4.27823e-14 2.00728e-13 0.965926" mesh="1_1_31_qt_942_1" material="1_1_31_qt_942_1_material"/>
            <!-- Part 1_1_06_eb903_538_1_2 -->
            <geom type="mesh" class="visual" pos="0.058 0.100459 -0.0991" quat="0.258819 -4.27823e-14 2.00728e-13 0.965926" mesh="1_1_06_eb903_538_1" material="1_1_06_eb903_538_1_material"/>
            <!-- Part 1_1_06_eb903_537_af0_1 -->
            <geom type="mesh" class="visual" pos="2.81719e-15 -4.82947e-15 -0.0375" quat="0.965926 -1.47119e-13 -4.9849e-14 -0.258819" mesh="1_1_06_eb903_537_af0_1" material="1_1_06_eb903_537_af0_1_material"/>
            <!-- Part 1_1_02_eb901_558_1 -->
            <geom type="mesh" class="visual" pos="-3.46945e-18 -2.77556e-17 1.38778e-17" quat="0 1 0 0" mesh="1_1_02_eb901_558_1" material="1_1_02_eb901_558_1_material"/>
            <!-- Part 1_1_06_eb903_537_af0_1_2 -->
            <geom type="mesh" class="visual" pos="0.058 0.100459 -0.08" quat="0.5 -6.85879e-14 -1.39222e-13 -0.866025" mesh="1_1_06_eb903_537_af0_1" material="1_1_06_eb903_537_af0_1_material"/>
            <!-- Part 1_1_02_eb901_558_1_2 -->
            <geom type="mesh" class="visual" pos="0.058 0.100459 -0.0425" quat="9.09565e-14 0.707107 -0.707107 1.21908e-13" mesh="1_1_02_eb901_558_1" material="1_1_02_eb901_558_1_material"/>
            <!-- Link shin_subassembly -->
            <body name="shin_subassembly" pos="0.17 0.294449 -0.0305" quat="1.46014e-13 0.962759 -0.270363 5.22601e-14">
              <!-- Joint from tigh_subassembly to shin_subassembly -->
              <joint axis="0 0 1" name="knee_right" type="hinge"/>
              <inertial pos="-0.0767411 -0.0485893 6.35117e-05" mass="0.593267" fullinertia="0.000596584 0.00138349 0.00175704 -0.000624998 -7.89922e-05 -4.8616e-05"/>
              <!-- Part hex_socket_head_cap_screw_m2_5x0_45_x_8__dec2226ceabd7d7ca0bb403ec234d89b -->
              <!-- Part rmdx43 -->
              <geom type="mesh" class="visual" pos="-0.295552 0.370644 0.019" quat="0.616262 0.616262 -0.346728 -0.346728" mesh="rmdx43" material="rmdx43_material"/>
              <!-- Part xt_30_2x2_f_3 -->
              <geom type="mesh" class="visual" pos="-0.0609859 -0.00236005 -0.0142" quat="0.346728 0.616262 -0.346728 0.616262" mesh="xt_30_2x2_f" material="xt_30_2x2_f_material"/>
              <!-- Part hex_socket_head_cap_screw_m3x0_50_x_20__7252065e4445f5ec71347b53fcae11e4 -->
              <!-- Part hex_socket_head_cap_screw_m3x0_50_x_10__9c80fcbba574884e63b580474e1ee150_4 -->
              <!-- Part tibias22 -->
              <geom type="mesh" class="visual" pos="-0.222223 -0.134971 0.019" quat="0.616262 -0.616262 0.346728 -0.346728" mesh="tibias22" material="tibias22_material"/>
              <!-- Part 27628_01_050_catpart -->
              <geom type="mesh" class="visual" pos="0.00445119 -0.0325026 0.02" quat="0.557146 -0.557146 0.435417 -0.435417" mesh="27628_01_050_catpart" material="27628_01_050_catpart_material"/>
              <!-- Part hex_socket_head_cap_screw_m3x0_50_x_10__9c80fcbba574884e63b580474e1ee150_5 -->
              <!-- Part hex_socket_head_cap_screw_m3x0_50_x_10__9c80fcbba574884e63b580474e1ee150_6 -->
              <!-- Part hex_socket_head_cap_screw_m3x0_50_x_10__9c80fcbba574884e63b580474e1ee150_7 -->
              <!-- Part hex_thin_nut_grade_a___b_m4x0_7__a8228d9ce5dcc05f24da0a2f74d882f3 -->
              <geom type="mesh" class="visual" pos="-1.38778e-17 5.55112e-17 0.0247602" quat="1 8.79998e-17 -5.55112e-17 -1.66533e-16" mesh="hex_thin_nut_grade_a___b_m4x0_7__a8228d9ce5dcc05f24da0a2f74d882f3" material="hex_thin_nut_grade_a___b_m4x0_7__a8228d9ce5dcc05f24da0a2f74d882f3_material"/>
              <!-- Part 07534_05x40_catpart -->
              <geom type="mesh" class="visual" pos="0 5.55112e-17 -0.025" quat="0.5 -0.5 -0.5 -0.5" mesh="07534_05x40_catpart" material="07534_05x40_catpart_material"/>
              <!-- Part hex_thin_nut_grade_a___b_m4x0_7__a8228d9ce5dcc05f24da0a2f74d882f3_2 -->
              <geom type="mesh" class="visual" pos="-0.0408481 -0.0600158 -0.0112398" quat="6.00228e-16 -0.998751 0.049956 -1.60429e-16" mesh="hex_thin_nut_grade_a___b_m4x0_7__a8228d9ce5dcc05f24da0a2f74d882f3" material="hex_thin_nut_grade_a___b_m4x0_7__a8228d9ce5dcc05f24da0a2f74d882f3_material"/>
              <!-- Part hex_socket_head_cap_screw_m3x0_50_x_20__7252065e4445f5ec71347b53fcae11e4_2 -->
              <!-- Part hex_socket_head_cap_screw_m3x0_50_x_10__9c80fcbba574884e63b580474e1ee150_8 -->
              <!-- Part 07534_05x20_catpart -->
              <geom type="mesh" class="visual" pos="-0.0408481 -0.0600158 -0.041" quat="0.0353242 0.706224 -0.0353242 0.706224" mesh="07534_05x20_catpart" material="07534_05x20_catpart_material"/>
              <!-- Part actuation_ankle -->
              <geom type="mesh" class="visual" pos="-0.029932 0.125718 -0.019" quat="0.706224 0.706224 -0.0353242 -0.0353242" mesh="actuation_ankle" material="actuation_ankle_material"/>
              <!-- Part hex_socket_head_cap_screw_m3x0_50_x_30__cb22dc4460edbee8e1cbddf29677c00f -->
              <!-- Part rmdx43_2 -->
              <geom type="mesh" class="visual" pos="-0.340851 0.343131 0.006" quat="0.616262 0.616262 -0.346728 -0.346728" mesh="rmdx43" material="rmdx43_material"/>
              <!-- Part hex_socket_head_cap_screw_m3x0_50_x_10__9c80fcbba574884e63b580474e1ee150_9 -->
              <!-- Part hex_socket_head_cap_screw_m3x0_50_x_20__7252065e4445f5ec71347b53fcae11e4_3 -->
              <!-- Part hex_socket_head_cap_screw_m3x0_50_x_10__9c80fcbba574884e63b580474e1ee150_10 -->
              <!-- Part hex_socket_head_cap_screw_m3x0_50_x_10__9c80fcbba574884e63b580474e1ee150_11 -->
              <!-- Part hex_socket_head_cap_screw_m3x0_50_x_10__9c80fcbba574884e63b580474e1ee150_12 -->
              <!-- Part hex_socket_head_cap_screw_m4x0_70_x_12__c825518ee8edf1afced0eee1b019b750_7 -->
              <!-- Part hex_socket_head_cap_screw_m3x0_50_x_20__7252065e4445f5ec71347b53fcae11e4_4 -->
              <!-- Part hex_socket_head_cap_screw_m3x0_50_x_20__7252065e4445f5ec71347b53fcae11e4_5 -->
              <!-- Part hex_socket_head_cap_screw_m3x0_50_x_10__9c80fcbba574884e63b580474e1ee150_13 -->
              <!-- Part hex_socket_head_cap_screw_m3x0_50_x_10__9c80fcbba574884e63b580474e1ee150_14 -->
              <!-- Part hex_socket_head_cap_screw_m3x0_50_x_10__9c80fcbba574884e63b580474e1ee150_15 -->
              <!-- Part hex_socket_head_cap_screw_m3x0_50_x_10__9c80fcbba574884e63b580474e1ee150_16 -->
              <!-- Part hex_socket_head_cap_screw_m3x0_50_x_20__7252065e4445f5ec71347b53fcae11e4_6 -->
              <!-- Part hex_socket_head_cap_screw_m3x0_50_x_10__9c80fcbba574884e63b580474e1ee150_17 -->
              <!-- Part hex_socket_head_cap_screw_m3x0_50_x_10__9c80fcbba574884e63b580474e1ee150_18 -->
              <!-- Part hex_socket_head_cap_screw_m3x0_50_x_10__9c80fcbba574884e63b580474e1ee150_19 -->
              <!-- Part hex_socket_head_cap_screw_m2_5x0_45_x_8__dec2226ceabd7d7ca0bb403ec234d89b_2 -->
              <!-- Part hex_socket_head_cap_screw_m4x0_70_x_12__c825518ee8edf1afced0eee1b019b750_8 -->
              <!-- Part hat_big -->
              <geom type="mesh" class="visual" pos="-0.222223 -0.134971 0.019" quat="0.616262 -0.616262 0.346728 -0.346728" mesh="hat_big" material="hat_big_material"/>
              <!-- Part 07534_05x20_catpart_2 -->
              <geom type="mesh" class="visual" pos="0.00445119 -0.0325026 0.041" quat="0.0353242 -0.706224 0.0353242 0.706224" mesh="07534_05x20_catpart" material="07534_05x20_catpart_material"/>
              <!-- Part hex_socket_head_cap_screw_m4x0_70_x_12__c825518ee8edf1afced0eee1b019b750_9 -->
              <!-- Part hex_thin_nut_grade_a___b_m4x0_7__a8228d9ce5dcc05f24da0a2f74d882f3_3 -->
              <geom type="mesh" class="visual" pos="0.00445119 -0.0325026 0.0134397" quat="0.998751 -1.45502e-13 1.29674e-13 -0.049956" mesh="hex_thin_nut_grade_a___b_m4x0_7__a8228d9ce5dcc05f24da0a2f74d882f3" material="hex_thin_nut_grade_a___b_m4x0_7__a8228d9ce5dcc05f24da0a2f74d882f3_material"/>
              <!-- Part hex_socket_head_cap_screw_m2_5x0_45_x_8__dec2226ceabd7d7ca0bb403ec234d89b_3 -->
              <!-- Part tibias12 -->
              <geom type="mesh" class="visual" pos="-0.222223 -0.134971 0.019" quat="0.616262 -0.616262 0.346728 -0.346728" mesh="tibias12" material="tibias12_material"/>
              <!-- Part hex_socket_head_cap_screw_m3x0_50_x_10__9c80fcbba574884e63b580474e1ee150_20 -->
              <!-- Part hex_socket_head_cap_screw_m3x0_50_x_20__7252065e4445f5ec71347b53fcae11e4_7 -->
              <!-- Part hex_socket_head_cap_screw_m3x0_50_x_10__9c80fcbba574884e63b580474e1ee150_21 -->
              <!-- Part hex_socket_head_cap_screw_m3x0_50_x_10__9c80fcbba574884e63b580474e1ee150_22 -->
              <!-- Part xt_30_2x2_f_4 -->
              <geom type="mesh" class="visual" pos="-0.105687 -0.0295099 0.0145" quat="0.616262 0.346728 0.616262 -0.346728" mesh="xt_30_2x2_f" material="xt_30_2x2_f_material"/>
              <!-- Part hex_socket_head_cap_screw_m3x0_50_x_10__9c80fcbba574884e63b580474e1ee150_23 -->
              <!-- Part hex_socket_head_cap_screw_m3x0_50_x_20__7252065e4445f5ec71347b53fcae11e4_8 -->
              <!-- Part actuation_ankle_2 -->
              <geom type="mesh" class="visual" pos="-0.105966 -0.208258 0.019" quat="0.706224 -0.706224 0.0353242 -0.0353242" mesh="actuation_ankle" material="actuation_ankle_material"/>
              <!-- Part hex_socket_head_cap_screw_m3x0_50_x_10__9c80fcbba574884e63b580474e1ee150_24 -->
              <!-- Part hex_socket_head_cap_screw_m4x0_70_x_12__c825518ee8edf1afced0eee1b019b750_10 -->
              <!-- Part hex_socket_head_cap_screw_m3x0_50_x_20__7252065e4445f5ec71347b53fcae11e4_9 -->
              <!-- Part hex_socket_head_cap_screw_m3x0_50_x_20__7252065e4445f5ec71347b53fcae11e4_10 -->
              <!-- Part 27628_01_050_catpart_2 -->
              <geom type="mesh" class="visual" pos="-0.0408481 -0.0600156 -0.023" quat="0.700312 -0.700312 -0.0977916 0.0977916" mesh="27628_01_050_catpart" material="27628_01_050_catpart_material"/>
              <!-- Part hex_socket_head_cap_screw_m3x0_50_x_10__9c80fcbba574884e63b580474e1ee150_25 -->
              <!-- Part hex_socket_head_cap_screw_m3x0_50_x_20__7252065e4445f5ec71347b53fcae11e4_11 -->
              <!-- Part hex_socket_head_cap_screw_m3x0_50_x_20__7252065e4445f5ec71347b53fcae11e4_12 -->
              <!-- Part hex_socket_head_cap_screw_m3x0_50_x_10__9c80fcbba574884e63b580474e1ee150_26 -->
              <!-- Part hex_socket_head_cap_screw_m3x0_50_x_10__9c80fcbba574884e63b580474e1ee150_27 -->
              <!-- Part 1_1_31_eb463_510_fl46blw10_48v_5n_m_de_2__fl46blw10_48v_5n_m_de -->
              <geom type="mesh" class="visual" pos="-0.0905985 -0.0550265 -0.0195" quat="5.98181e-15 -0.759118 0.650953 -2.71078e-15" mesh="1_1_31_eb463_510_fl46blw10_48v_5n_m_de_2__fl46blw10_48v_5n_m_de" material="1_1_31_eb463_510_fl46blw10_48v_5n_m_de_2__fl46blw10_48v_5n_m_de_material"/>
              <!-- Part 1_1_02_eb461_502_fl46blw10_48v_5n_m_de_2__fl46blw10_48v_5n_m_de -->
              <geom type="mesh" class="visual" pos="-0.0905985 -0.0550265 -0.0095" quat="5.98181e-15 -0.759118 0.650953 -2.71078e-15" mesh="1_1_02_eb461_502_fl46blw10_48v_5n_m_de_2__fl46blw10_48v_5n_m_de" material="1_1_02_eb461_502_fl46blw10_48v_5n_m_de_2__fl46blw10_48v_5n_m_de_material"/>
              <!-- Part 1_1_06_eb463_509_fl46blw10_48v_5n_m_de_2__fl46blw10_48v_5n_m_de -->
              <geom type="mesh" class="visual" pos="-0.0905985 -0.0550265 0.022" quat="4.13917e-14 0.992834 -0.119504 3.69067e-14" mesh="1_1_06_eb463_509_fl46blw10_48v_5n_m_de_2__fl46blw10_48v_5n_m_de" material="1_1_06_eb463_509_fl46blw10_48v_5n_m_de_2__fl46blw10_48v_5n_m_de_material"/>
              <!-- Part 1_1_06_eb463_507_fl46blw10_48v_5n_m_de_2__fl46blw10_48v_5n_m_de -->
              <geom type="mesh" class="visual" pos="-0.0905985 -0.0550265 0.0085" quat="3.59039e-17 -0.871527 0.490348 2.73537e-16" mesh="1_1_06_eb463_507_fl46blw10_48v_5n_m_de_2__fl46blw10_48v_5n_m_de" material="1_1_06_eb463_507_fl46blw10_48v_5n_m_de_2__fl46blw10_48v_5n_m_de_material"/>
              <!-- Part 1_1_31_eb463_510_fl46blw10_48v_5n_m_de_2__fl46blw10_48v_5n_m_de_2 -->
              <geom type="mesh" class="visual" pos="-0.0452992 -0.0275132 0.0195" quat="0.950443 3.16414e-15 7.99361e-15 -0.3109" mesh="1_1_31_eb463_510_fl46blw10_48v_5n_m_de_2__fl46blw10_48v_5n_m_de" material="1_1_31_eb463_510_fl46blw10_48v_5n_m_de_2__fl46blw10_48v_5n_m_de_material"/>
              <!-- Part 1_1_02_eb461_502_fl46blw10_48v_5n_m_de_2__fl46blw10_48v_5n_m_de_2 -->
              <geom type="mesh" class="visual" pos="-0.0452992 -0.0275132 0.0095" quat="0.950443 3.16414e-15 7.99361e-15 -0.3109" mesh="1_1_02_eb461_502_fl46blw10_48v_5n_m_de_2__fl46blw10_48v_5n_m_de" material="1_1_02_eb461_502_fl46blw10_48v_5n_m_de_2__fl46blw10_48v_5n_m_de_material"/>
              <!-- Part 1_1_06_eb463_509_fl46blw10_48v_5n_m_de_2__fl46blw10_48v_5n_m_de_2 -->
              <geom type="mesh" class="visual" pos="-0.0452992 -0.0275132 -0.022" quat="0.617538 -2.18762e-14 -3.63043e-14 -0.786541" mesh="1_1_06_eb463_509_fl46blw10_48v_5n_m_de_2__fl46blw10_48v_5n_m_de" material="1_1_06_eb463_509_fl46blw10_48v_5n_m_de_2__fl46blw10_48v_5n_m_de_material"/>
              <!-- Part 1_1_06_eb463_507_fl46blw10_48v_5n_m_de_2__fl46blw10_48v_5n_m_de_2 -->
              <geom type="mesh" class="visual" pos="-0.0452992 -0.0275132 -0.0085" quat="0.871527 1.24034e-16 2.77556e-16 -0.490348" mesh="1_1_06_eb463_507_fl46blw10_48v_5n_m_de_2__fl46blw10_48v_5n_m_de" material="1_1_06_eb463_507_fl46blw10_48v_5n_m_de_2__fl46blw10_48v_5n_m_de_material"/>
              <!-- Part 0001755652_1_1_30_gr_2202_asm_1_asm_1_1_30_gr_2202_asm_fl46blw10_48v_5n_m_de_2__fl46blw10_48v_5n_m_de -->
              <geom type="mesh" class="visual" pos="-0.0824788 -0.0500948 -0.024" quat="0.490348 5.32206e-18 -3.53016e-16 0.871527" mesh="0001755652_1_1_30_gr_2202_asm_1_asm_1_1_30_gr_2202_asm_fl46blw10_48v_5n_m_de_2__fl46blw10_48v_5n_m_de" material="0001755652_1_1_30_gr_2202_asm_1_asm_1_1_30_gr_2202_asm_fl46blw10_48v_5n_m_de_2__fl46blw10_48v_5n_m_de_material"/>
              <!-- Part 0001755652_1_1_30_gr_2202_asm_1_asm_1_1_30_gr_2202_asm_fl46blw10_48v_5n_m_de_2__fl46blw10_48v_5n_m_de_2 -->
              <geom type="mesh" class="visual" pos="-0.0989292 -0.0504604 -0.024" quat="0.490348 5.32206e-18 -3.53016e-16 0.871527" mesh="0001755652_1_1_30_gr_2202_asm_1_asm_1_1_30_gr_2202_asm_fl46blw10_48v_5n_m_de_2__fl46blw10_48v_5n_m_de" material="0001755652_1_1_30_gr_2202_asm_1_asm_1_1_30_gr_2202_asm_fl46blw10_48v_5n_m_de_2__fl46blw10_48v_5n_m_de_material"/>
              <!-- Part 0001755652_1_1_30_gr_2202_asm_1_asm_1_1_30_gr_2202_asm_fl46blw10_48v_5n_m_de_2__fl46blw10_48v_5n_m_de_3 -->
              <geom type="mesh" class="visual" pos="-0.0534189 -0.0324449 0.024" quat="5.11527e-14 -0.490348 -0.871527 1.88021e-13" mesh="0001755652_1_1_30_gr_2202_asm_1_asm_1_1_30_gr_2202_asm_fl46blw10_48v_5n_m_de_2__fl46blw10_48v_5n_m_de" material="0001755652_1_1_30_gr_2202_asm_1_asm_1_1_30_gr_2202_asm_fl46blw10_48v_5n_m_de_2__fl46blw10_48v_5n_m_de_material"/>
              <!-- Part 0001755652_1_1_30_gr_2202_asm_1_asm_1_1_30_gr_2202_asm_fl46blw10_48v_5n_m_de_2__fl46blw10_48v_5n_m_de_4 -->
              <geom type="mesh" class="visual" pos="-0.0455103 -0.0180156 0.024" quat="5.11527e-14 -0.490348 -0.871527 1.88021e-13" mesh="0001755652_1_1_30_gr_2202_asm_1_asm_1_1_30_gr_2202_asm_fl46blw10_48v_5n_m_de_2__fl46blw10_48v_5n_m_de" material="0001755652_1_1_30_gr_2202_asm_1_asm_1_1_30_gr_2202_asm_fl46blw10_48v_5n_m_de_2__fl46blw10_48v_5n_m_de_material"/>
              <!-- Part 0001755652_00mini_000_asm_1_asm_1_asm_00mini__20250103_a0001_asm_1_as_asm_1_1_30_gr_2202_asm_1_asm_1_1_30_gr_2202_asm_fl46blw10_48v_5n_m_de_2__fl46blw10_48v_5n_m_de -->
              <geom type="mesh" class="visual" pos="-0.0903874 -0.0645241 -0.024" quat="0.490348 5.32206e-18 -3.53016e-16 0.871527" mesh="0001755652_00mini_000_asm_1_asm_1_asm_00mini__20250103_a0001_asm_1_as_asm_1_1_30_gr_2202_asm_1_asm_1_1_30_gr_2202_asm_fl46blw10_48v_5n_m_de_2__fl46blw10_48v_5n_m_de" material="0001755652_00mini_000_asm_1_asm_1_asm_00mini__20250103_a0001_asm_1_as_asm_1_1_30_gr_2202_asm_1_asm_1_1_30_gr_2202_asm_fl46blw10_48v_5n_m_de_2__fl46blw10_48v_5n_m_de_material"/>
              <!-- Part 6706__300001_1_1_00mini_000_asm_1_asm_1_asm_00mini__20250103_a0001_asm_1_as_asm_1_1_30_gr_2202_asm_1_asm_1_1_30_gr_2202_asm_fl46blw10_48v_5n_m_de_2__fl46blw10_48v_5n_m_de -->
              <geom type="mesh" class="visual" pos="-0.0905985 -0.0550265 -0.0205" quat="0.490348 5.32206e-18 -3.53016e-16 0.871527" mesh="6706__300001_1_1_00mini_000_asm_1_asm_1_asm_00mini__20250103_a0001_asm_1_as_asm_1_1_30_gr_2202_asm_1_asm_1_1_30_gr_2202_asm_fl46blw10_48v_5n_m_de_2__fl46blw10_48v_5n_m_de" material="6706__300001_1_1_00mini_000_asm_1_asm_1_asm_00mini__20250103_a0001_asm_1_as_asm_1_1_30_gr_2202_asm_1_asm_1_1_30_gr_2202_asm_fl46blw10_48v_5n_m_de_2__fl46blw10_48v_5n_m_de_material"/>
              <!-- Part 0001755650_00mini_000_asm_1_asm_1_asm_00mini__20250103_a0001_asm_1_as_asm_1_1_30_gr_2202_asm_1_asm_1_1_30_gr_2202_asm_fl46blw10_48v_5n_m_de_2__fl46blw10_48v_5n_m_de -->
              <geom type="mesh" class="visual" pos="-0.0905985 -0.0550265 -0.0209" quat="0.490348 5.32206e-18 -3.53016e-16 0.871527" mesh="0001755650_00mini_000_asm_1_asm_1_asm_00mini__20250103_a0001_asm_1_as_asm_1_1_30_gr_2202_asm_1_asm_1_1_30_gr_2202_asm_fl46blw10_48v_5n_m_de_2__fl46blw10_48v_5n_m_de" material="0001755650_00mini_000_asm_1_asm_1_asm_00mini__20250103_a0001_asm_1_as_asm_1_1_30_gr_2202_asm_1_asm_1_1_30_gr_2202_asm_fl46blw10_48v_5n_m_de_2__fl46blw10_48v_5n_m_de_material"/>
              <!-- Part 0001755652_00mini_000_asm_1_asm_1_asm_00mini__20250103_a0001_asm_1_as_asm_1_1_30_gr_2202_asm_1_asm_1_1_30_gr_2202_asm_fl46blw10_48v_5n_m_de_2__fl46blw10_48v_5n_m_de_2 -->
              <geom type="mesh" class="visual" pos="-0.0369685 -0.0320793 0.024" quat="5.11527e-14 -0.490348 -0.871527 1.88021e-13" mesh="0001755652_00mini_000_asm_1_asm_1_asm_00mini__20250103_a0001_asm_1_as_asm_1_1_30_gr_2202_asm_1_asm_1_1_30_gr_2202_asm_fl46blw10_48v_5n_m_de_2__fl46blw10_48v_5n_m_de" material="0001755652_00mini_000_asm_1_asm_1_asm_00mini__20250103_a0001_asm_1_as_asm_1_1_30_gr_2202_asm_1_asm_1_1_30_gr_2202_asm_fl46blw10_48v_5n_m_de_2__fl46blw10_48v_5n_m_de_material"/>
              <!-- Part 6706__300001_1_1_00mini_000_asm_1_asm_1_asm_00mini__20250103_a0001_asm_1_as_asm_1_1_30_gr_2202_asm_1_asm_1_1_30_gr_2202_asm_fl46blw10_48v_5n_m_de_2__fl46blw10_48v_5n_m_de_2 -->
              <geom type="mesh" class="visual" pos="-0.0452992 -0.0275132 0.0205" quat="5.11527e-14 -0.490348 -0.871527 1.88021e-13" mesh="6706__300001_1_1_00mini_000_asm_1_asm_1_asm_00mini__20250103_a0001_asm_1_as_asm_1_1_30_gr_2202_asm_1_asm_1_1_30_gr_2202_asm_fl46blw10_48v_5n_m_de_2__fl46blw10_48v_5n_m_de" material="6706__300001_1_1_00mini_000_asm_1_asm_1_asm_00mini__20250103_a0001_asm_1_as_asm_1_1_30_gr_2202_asm_1_asm_1_1_30_gr_2202_asm_fl46blw10_48v_5n_m_de_2__fl46blw10_48v_5n_m_de_material"/>
              <!-- Part 0001755650_00mini_000_asm_1_asm_1_asm_00mini__20250103_a0001_asm_1_as_asm_1_1_30_gr_2202_asm_1_asm_1_1_30_gr_2202_asm_fl46blw10_48v_5n_m_de_2__fl46blw10_48v_5n_m_de_2 -->
              <geom type="mesh" class="visual" pos="-0.0452992 -0.0275132 0.0209" quat="5.11527e-14 -0.490348 -0.871527 1.88021e-13" mesh="0001755650_00mini_000_asm_1_asm_1_asm_00mini__20250103_a0001_asm_1_as_asm_1_1_30_gr_2202_asm_1_asm_1_1_30_gr_2202_asm_fl46blw10_48v_5n_m_de_2__fl46blw10_48v_5n_m_de" material="0001755650_00mini_000_asm_1_asm_1_asm_00mini__20250103_a0001_asm_1_as_asm_1_1_30_gr_2202_asm_1_asm_1_1_30_gr_2202_asm_fl46blw10_48v_5n_m_de_2__fl46blw10_48v_5n_m_de_material"/>
              <!-- Link ankle_subassembly -->
              <body name="ankle_subassembly" pos="-0.222223 -0.134971 0.02" quat="1.86458e-14 -0.836075 -0.548616 1.00894e-14">
                <!-- Joint from shin_subassembly to ankle_subassembly -->
                <joint axis="0 0 1" name="ankley_right" type="hinge"/>
                <inertial pos="-1.62086e-08 -0.000727483 0.02" mass="0.0168168" fullinertia="5.19458e-06 4.86353e-06 8.35665e-07 2.61119e-12 4.35145e-12 -7.24871e-13"/>
                <!-- Part hex_socket_head_cap_screw_m2_5x0_45_x_6__ec244025d76f8b83b2775022a2cb3232_7 -->
                <!-- Part 07534_05x40_catpart_2 -->
                <geom type="mesh" class="visual" pos="9.99201e-16 0.0249999 0.02" quat="2.53644e-14 -0.707107 0.707107 5.23701e-16" mesh="07534_05x40_catpart" material="07534_05x40_catpart_material"/>
                <!-- Part ujoint -->
                <geom type="mesh" class="visual" pos="-1.33227e-15 2.56739e-16 0.02" quat="1.40063e-14 0.707107 5.54001e-14 -0.707107" mesh="ujoint" material="ujoint_material"/>
                <!-- Part hex_socket_head_cap_screw_m2_5x0_45_x_6__ec244025d76f8b83b2775022a2cb3232_8 -->
                <!-- Part spacer_ujoint -->
                <geom type="mesh" class="visual" pos="-1.9984e-15 -1.249e-16 0.02" quat="0.714619 -3.06292e-15 -0.699514 -3.52496e-15" mesh="spacer_ujoint" material="spacer_ujoint_material"/>
                <!-- Part hex_thin_nut_grade_a___b_m4x0_7__a8228d9ce5dcc05f24da0a2f74d882f3_4 -->
                <geom type="mesh" class="visual" pos="2.88658e-14 -0.02204 0.02" quat="0.505312 -0.505312 -0.494631 -0.494631" mesh="hex_thin_nut_grade_a___b_m4x0_7__a8228d9ce5dcc05f24da0a2f74d882f3" material="hex_thin_nut_grade_a___b_m4x0_7__a8228d9ce5dcc05f24da0a2f74d882f3_material"/>
                <!-- Part part_3_2 -->
                <geom type="mesh" class="visual" pos="1.55431e-15 -3.98293e-15 0.0195" quat="1.49421e-14 0.707107 5.65104e-14 -0.707107" mesh="part_3" material="part_3_material"/>
                <!-- Part bearing_5_16_5_3 -->
                <geom type="mesh" class="visual" pos="-6.32827e-15 -0.01594 0.02" quat="0.714619 -2.65277e-14 -0.699514 3.74527e-15" mesh="bearing_5_16_5" material="bearing_5_16_5_material"/>
                <!-- Part bearing_15_21_4_6 -->
                <geom type="mesh" class="visual" pos="0 0 0" quat="0.707107 0.707107 -0 -4.673e-31" mesh="bearing_15_21_4" material="bearing_15_21_4_material"/>
                <!-- Part hex_socket_head_cap_screw_m2_5x0_45_x_6__ec244025d76f8b83b2775022a2cb3232_9 -->
                <!-- Part hex_socket_head_cap_screw_m2_5x0_45_x_6__ec244025d76f8b83b2775022a2cb3232_10 -->
                <!-- Part part_3_3 -->
                <geom type="mesh" class="visual" pos="2.66454e-15 -6.2797e-16 0.0205" quat="8.06898e-14 -0.707107 -5.21805e-15 -0.707107" mesh="part_3" material="part_3_material"/>
                <!-- Part hex_socket_head_cap_screw_m2_5x0_45_x_6__ec244025d76f8b83b2775022a2cb3232_11 -->
                <!-- Part hex_socket_head_cap_screw_m2_5x0_45_x_6__ec244025d76f8b83b2775022a2cb3232_12 -->
                <!-- Part bearing_5_16_5_4 -->
                <geom type="mesh" class="visual" pos="-7.77156e-15 0.0209456 0.02" quat="0.00732917 5.32411e-14 0.999973 -3.55757e-14" mesh="bearing_5_16_5" material="bearing_5_16_5_material"/>
                <!-- Part spacer_ujoint_2 -->
                <geom type="mesh" class="visual" pos="-7.21645e-15 5.64895e-06 0.02" quat="4.0946e-15 0.71227 -2.69784e-14 -0.701905" mesh="spacer_ujoint" material="spacer_ujoint_material"/>
                <!-- Part bearing_15_21_4_7 -->
                <geom type="mesh" class="visual" pos="-1.11022e-15 1.89432e-15 0.04" quat="5.55112e-16 6.64504e-16 0.707107 -0.707107" mesh="bearing_15_21_4" material="bearing_15_21_4_material"/>
                <!-- Link foot_subassembly -->
                <body name="foot_subassembly" pos="-6.32827e-15 -0.01594 0.02" quat="0.5 0.5 0.5 -0.5">
                  <!-- Joint from ankle_subassembly to foot_subassembly -->
                  <joint axis="0 0 1" name="anklex_right" type="hinge"/>
                  <inertial pos="8.52312e-09 -0.0138418 -0.052232" mass="0.122498" fullinertia="0.000163413 0.000162266 7.07692e-05 -1.15065e-10 -2.96383e-11 1.11374e-05"/>
                  <!-- Part hex_socket_head_cap_screw_m2_5x0_45_x_6__ec244025d76f8b83b2775022a2cb3232_13 -->
                  <!-- Part 27628_01_050_catpart_3 -->
                  <geom type="mesh" class="visual" pos="0.021 3.53792e-08 -0.0660002" quat="4.79945e-16 0.707107 0.707107 -5.68262e-16" mesh="27628_01_050_catpart" material="27628_01_050_catpart_material"/>
                  <!-- Part hex_socket_head_cap_screw_m2_5x0_45_x_6__ec244025d76f8b83b2775022a2cb3232_14 -->
                  <!-- Part 07534_05x20_catpart_3 -->
                  <geom type="mesh" class="visual" pos="0.036 0 -0.066" quat="7.77156e-16 1.85488e-15 -1 1.72085e-15" mesh="07534_05x20_catpart" material="07534_05x20_catpart_material"/>
                  <!-- Part 27628_01_050_catpart_4 -->
                  <geom type="mesh" class="visual" pos="-0.021 -1.89504e-08 -0.066" quat="4.39833e-17 -0.707107 -0.707107 3.45214e-17" mesh="27628_01_050_catpart" material="27628_01_050_catpart_material"/>
                  <!-- Part 07534_05x20_catpart_4 -->
                  <geom type="mesh" class="visual" pos="-0.036 1.11022e-16 -0.066" quat="1 -2.41011e-15 3.33067e-16 -1.13798e-15" mesh="07534_05x20_catpart" material="07534_05x20_catpart_material"/>
                  <!-- Part hat_small -->
                  <geom type="mesh" class="visual" pos="6.52256e-16 -0.035 -0.0385" quat="0.5 -0.5 -0.5 -0.5" mesh="hat_small" material="hat_small_material"/>
                  <!-- Part hex_socket_head_cap_screw_m2_5x0_45_x_6__ec244025d76f8b83b2775022a2cb3232_15 -->
                  <!-- Part foot -->
                  <geom type="mesh" class="visual" pos="1.11022e-16 -0.035 -0.0385" quat="0.5 -0.5 -0.5 -0.5" mesh="foot" material="foot_material"/>
                  <geom name="right_foot1_collision" class="collision" type="capsule" size="0.015 0.05" fromto="-0.032 -0.02 0.005 0.032 -0.02 0.005"/>
                  <geom name="right_foot2_collision" class="collision" type="capsule" size="0.015 0.05" fromto="-0.032 -0.02 -0.10 0.032 -0.02 -0.10"/>
                  <geom name="right_foot3_collision" class="collision" type="capsule" size="0.015 0.05" fromto="-0.032 -0.02 0.005 -0.032 -0.02 -0.10"/>
                  <geom name="right_foot4_collision" class="collision" type="capsule" size="0.015 0.05" fromto="0.032 -0.02 0.005 0.032 -0.02 -0.10"/>
                  <geom name="right_foot5_collision" class="collision" type="capsule" size="0.015 0.05" fromto="-0.032 -0.02 -0.02 0.032 -0.02 -0.02"/>
                  <geom name="right_foot6_collision" class="collision" type="capsule" size="0.015 0.05" fromto="-0.032 -0.02 -0.06 0.032 -0.02 -0.06"/>
                  <!-- Frame foot_right -->
                  <site group="3" name="foot_right" pos="-6.35351e-08 -0.035 -0.0480606" quat="0.5 -0.5 0.5 0.5"/>
                </body>
              </body>
            </body>
          </body>
        </body>
      </body>
      <!-- Link hipx_subassemby_sym -->
      <body name="hipx_subassemby_sym" pos="-0.000819037 0.13316 0.04164" quat="0.821908 -0.0571233 0.0414078 0.565234">
        <!-- Joint from torso_subassembly to hipx_subassemby_sym -->
        <joint axis="0 0 1" name="hipz_left" type="hinge"/>
        <inertial pos="-0.0179432 0.0274245 -0.0837272" mass="0.794016" fullinertia="0.00093784 0.000903443 0.00100402 4.40289e-05 -0.000110464 0.000168604"/>
        <!-- Part rs02_2 -->
        <!-- Part hex_socket_head_cap_screw_m4x0_70_x_40__14321d45d56569246e7feb4574a6bae6_15 -->
        <!-- Part robstride02_2 -->
        <geom type="mesh" class="visual" pos="-0.575896 0.057308 -0.20175" quat="0.60316 -0.792908 -0.0689068 -0.0524169" mesh="robstride02" material="robstride02_material"/>
        <!-- Part hex_socket_head_cap_screw_m3x0_50_x_8__d566997e1880d7fd3377c5b0ee12206c_28 -->
        <!-- Part hex_socket_head_cap_screw_m3x0_50_x_8__d566997e1880d7fd3377c5b0ee12206c_29 -->
        <!-- Part hex_socket_head_cap_screw_m3x0_50_x_8__d566997e1880d7fd3377c5b0ee12206c_30 -->
        <!-- Part hex_socket_head_cap_screw_m3x0_50_x_8__d566997e1880d7fd3377c5b0ee12206c_31 -->
        <!-- Part hipz22_sym -->
        <geom type="mesh" class="visual" pos="2.77556e-17 6.93889e-18 0.1" quat="1 -0 2.77556e-17 3.18755e-17" mesh="hipz22_sym" material="hipz22_sym_material"/>
        <!-- Part hex_socket_head_cap_screw_m4x0_70_x_40__14321d45d56569246e7feb4574a6bae6_16 -->
        <!-- Part hipz12_sym -->
        <geom type="mesh" class="visual" pos="1.38778e-17 -2.08167e-17 0.1" quat="1 1.77786e-18 1.38778e-17 -4.16334e-17" mesh="hipz12_sym" material="hipz12_sym_material"/>
        <!-- Part xt_30_2x2_f_5 -->
        <geom type="mesh" class="visual" pos="-0.0280156 0.0769561 -0.0718124" quat="0.498768 0.406175 -0.443127 0.624413" mesh="xt_30_2x2_f" material="xt_30_2x2_f_material"/>
        <!-- Part hex_socket_head_cap_screw_m3x0_50_x_8__d566997e1880d7fd3377c5b0ee12206c_32 -->
        <!-- Part hex_socket_head_cap_screw_m3x0_50_x_8__d566997e1880d7fd3377c5b0ee12206c_33 -->
        <!-- Part hex_socket_head_cap_screw_m3x0_50_x_8__d566997e1880d7fd3377c5b0ee12206c_34 -->
        <!-- Part hex_socket_head_cap_screw_m4x0_70_x_40__14321d45d56569246e7feb4574a6bae6_17 -->
        <!-- Part hex_socket_head_cap_screw_m3x0_50_x_8__d566997e1880d7fd3377c5b0ee12206c_35 -->
        <!-- Part hex_socket_head_cap_screw_m4x0_70_x_40__14321d45d56569246e7feb4574a6bae6_18 -->
        <!-- Part hex_socket_head_cap_screw_m4x0_70_x_40__14321d45d56569246e7feb4574a6bae6_19 -->
        <!-- Part hex_socket_head_cap_screw_m4x0_70_x_40__14321d45d56569246e7feb4574a6bae6_20 -->
        <!-- Part hex_socket_head_cap_screw_m3x0_50_x_8__d566997e1880d7fd3377c5b0ee12206c_36 -->
        <!-- Part hex_socket_head_cap_screw_m4x0_70_x_40__14321d45d56569246e7feb4574a6bae6_21 -->
        <!-- Part hex_socket_head_cap_screw_m3x0_50_x_8__d566997e1880d7fd3377c5b0ee12206c_37 -->
        <!-- Part hex_socket_head_cap_screw_m3x0_50_x_8__d566997e1880d7fd3377c5b0ee12206c_38 -->
        <!-- Part hex_socket_head_cap_screw_m4x0_70_x_40__14321d45d56569246e7feb4574a6bae6_22 -->
        <!-- Part bearing_35_72_17_4 -->
        <geom type="mesh" class="visual" pos="-0.01759 0.0267968 -0.104484" quat="0.792908 0.60316 -0.0524169 0.0689068" mesh="bearing_35_72_17" material="bearing_35_72_17_material"/>
        <!-- Part hex_socket_head_cap_screw_m3x0_50_x_8__d566997e1880d7fd3377c5b0ee12206c_39 -->
        <!-- Part hex_socket_head_cap_screw_m4x0_70_x_40__14321d45d56569246e7feb4574a6bae6_23 -->
        <!-- Part hex_socket_head_cap_screw_m3x0_50_x_8__d566997e1880d7fd3377c5b0ee12206c_40 -->
        <!-- Part hex_socket_head_cap_screw_m3x0_50_x_8__d566997e1880d7fd3377c5b0ee12206c_41 -->
        <!-- Part hex_socket_head_cap_screw_m4x0_70_x_40__14321d45d56569246e7feb4574a6bae6_24 -->
        <!-- Part hex_socket_head_cap_screw_m3x0_50_x_8__d566997e1880d7fd3377c5b0ee12206c_42 -->
        <!-- Link hipy_subassembly_sym -->
        <body name="hipy_subassembly_sym" pos="-0.01897 0.0289 -0.09689" quat="0.388859 -0.13275 0.0879729 0.907429">
          <!-- Joint from hipx_subassemby_sym to hipy_subassembly_sym -->
          <joint axis="0 0 1" name="hipx_left" type="hinge"/>
          <inertial pos="0.0047654 0.00266393 -0.0607296" mass="0.241619" fullinertia="0.000504046 0.000455768 0.000428972 -2.43365e-05 7.8493e-06 3.61482e-05"/>
          <!-- Part hex_socket_head_cap_screw_m4x0_70_x_12__c825518ee8edf1afced0eee1b019b750_11 -->
          <!-- Part hex_socket_head_cap_screw_m4x0_70_x_12__c825518ee8edf1afced0eee1b019b750_12 -->
          <!-- Part hex_socket_head_cap_screw_m4x0_70_x_12__c825518ee8edf1afced0eee1b019b750_13 -->
          <!-- Part hex_socket_head_cap_screw_m4x0_70_x_12__c825518ee8edf1afced0eee1b019b750_14 -->
          <!-- Part hex_socket_head_cap_screw_m4x0_70_x_20__832e47d784177ea3f1dabbaab534416e_23 -->
          <!-- Part hex_socket_head_cap_screw_m4x0_70_x_20__832e47d784177ea3f1dabbaab534416e_24 -->
          <!-- Part hipxy_sym -->
          <geom type="mesh" class="visual" pos="7.80626e-18 0 0" quat="0 1 0 0" mesh="hipxy_sym" material="hipxy_sym_material"/>
          <!-- Part hex_socket_head_cap_screw_m4x0_70_x_12__c825518ee8edf1afced0eee1b019b750_15 -->
          <!-- Part hex_socket_head_cap_screw_m4x0_70_x_20__832e47d784177ea3f1dabbaab534416e_25 -->
          <!-- Part hex_socket_head_cap_screw_m4x0_70_x_12__c825518ee8edf1afced0eee1b019b750_16 -->
          <!-- Part hex_socket_head_cap_screw_m4x0_70_x_20__832e47d784177ea3f1dabbaab534416e_26 -->
          <!-- Part hex_socket_head_cap_screw_m4x0_70_x_20__832e47d784177ea3f1dabbaab534416e_27 -->
          <!-- Part hex_socket_head_cap_screw_m4x0_70_x_20__832e47d784177ea3f1dabbaab534416e_28 -->
          <!-- Link tigh_subassembly_sym -->
          <body name="tigh_subassembly_sym" pos="0.012638 0.0276823 -0.112055" quat="0.0585807 -0.358948 -0.636245 -0.680379">
            <!-- Joint from hipy_subassembly_sym to tigh_subassembly_sym -->
            <joint axis="0 0 1" name="hipy_left" type="hinge"/>
            <inertial pos="-0.0431321 -0.0830741 -0.0353867" mass="2.5804" fullinertia="0.0180602 0.00826187 0.0238429 -0.00802639 -0.00087206 -0.00158484"/>
            <!-- Part knee_rod22_sym -->
            <geom type="mesh" class="visual" pos="-0.058 -0.280519 0.0295" quat="0.707107 -0.707107 -1.77636e-15 3.14138e-16" mesh="knee_rod22_sym" material="knee_rod22_sym_material"/>
            <!-- Part hex_socket_head_cap_screw_m4x0_70_x_16__8d628c0d7a90368385b1c4c7479647eb_7 -->
            <!-- Part hex_socket_head_cap_screw_m2_5x0_45_x_6__ec244025d76f8b83b2775022a2cb3232_16 -->
            <!-- Part hex_socket_head_cap_screw_m4x0_70_x_8__a416dc2a8d778a4ef6150c0739aa89d1_15 -->
            <!-- Part hex_socket_head_cap_screw_m4x0_70_x_8__a416dc2a8d778a4ef6150c0739aa89d1_16 -->
            <!-- Part hex_socket_head_cap_screw_m4x0_70_x_8__a416dc2a8d778a4ef6150c0739aa89d1_17 -->
            <!-- Part hex_socket_head_cap_screw_m2_5x0_45_x_6__ec244025d76f8b83b2775022a2cb3232_17 -->
            <!-- Part hex_socket_head_cap_screw_m4x0_70_x_16__8d628c0d7a90368385b1c4c7479647eb_8 -->
            <!-- Part hex_socket_head_cap_screw_m4x0_70_x_40__14321d45d56569246e7feb4574a6bae6_25 -->
            <!-- Part hex_socket_head_cap_screw_m4x0_70_x_8__a416dc2a8d778a4ef6150c0739aa89d1_18 -->
            <!-- Part hex_socket_head_cap_screw_m4x0_70_x_8__a416dc2a8d778a4ef6150c0739aa89d1_19 -->
            <!-- Part hex_socket_head_cap_screw_m4x0_70_x_8__a416dc2a8d778a4ef6150c0739aa89d1_20 -->
            <!-- Part hex_socket_head_cap_screw_m4x0_70_x_16__8d628c0d7a90368385b1c4c7479647eb_9 -->
            <!-- Part bearing_15_21_4_8 -->
            <geom type="mesh" class="visual" pos="-0.221927 -0.268257 -0.0185" quat="0.5 -0.5 -0.5 0.5" mesh="bearing_15_21_4" material="bearing_15_21_4_material"/>
            <!-- Part part_3_4 -->
            <geom type="mesh" class="visual" pos="-2.9976e-15 5.44009e-15 -0.0938" quat="0.683013 0.183013 0.683013 -0.183013" mesh="part_3" material="part_3_material"/>
            <!-- Part bearing_15_21_4_9 -->
            <geom type="mesh" class="visual" pos="-0.102915 -0.0784891 -0.0245" quat="0.707107 -0.707107 -1.66533e-15 1.25743e-15" mesh="bearing_15_21_4" material="bearing_15_21_4_material"/>
            <!-- Part hex_socket_head_cap_screw_m4x0_70_x_40__14321d45d56569246e7feb4574a6bae6_26 -->
            <!-- Part hex_socket_head_cap_screw_m4x0_70_x_8__a416dc2a8d778a4ef6150c0739aa89d1_21 -->
            <!-- Part bearing_15_21_4_10 -->
            <geom type="mesh" class="visual" pos="-3.66374e-15 3.81639e-15 -0.0675" quat="0.183013 -0.183013 -0.683013 0.683013" mesh="bearing_15_21_4" material="bearing_15_21_4_material"/>
            <!-- Part bearing_15_21_4_11 -->
            <geom type="mesh" class="visual" pos="-0.102915 -0.0784891 -0.0365" quat="0.707107 0.707107 4.44089e-16 1.87502e-15" mesh="bearing_15_21_4" material="bearing_15_21_4_material"/>
            <!-- Part bearing_15_21_4_12 -->
            <geom type="mesh" class="visual" pos="-0.221927 -0.268257 -0.0465" quat="0.5 -0.5 -0.5 0.5" mesh="bearing_15_21_4" material="bearing_15_21_4_material"/>
            <!-- Part hex_socket_head_cap_screw_m2_5x0_45_x_6__ec244025d76f8b83b2775022a2cb3232_18 -->
            <!-- Part hex_socket_head_cap_screw_m4x0_70_x_16__8d628c0d7a90368385b1c4c7479647eb_10 -->
            <!-- Part hex_socket_head_cap_screw_m4x0_70_x_8__a416dc2a8d778a4ef6150c0739aa89d1_22 -->
            <!-- Part hex_socket_head_cap_screw_m4x0_70_x_40__14321d45d56569246e7feb4574a6bae6_27 -->
            <!-- Part femur_12_sym -->
            <geom type="mesh" class="visual" pos="-0.17 -0.294449 0.0295" quat="0.683013 -0.683013 0.183013 -0.183013" mesh="femur_12_sym" material="femur_12_sym_material"/>
            <geom name="femur_12_sym_collision" type="capsule" size="0.05 0.18" class="collision" pos="-0.17 -0.294449 0.0295" quat="0.683013 -0.683013 0.183013 -0.183013"/>
            <!-- Part bearing_5_16_5_5 -->
            <geom type="mesh" class="visual" pos="-0.17 -0.294449 -0.045" quat="0.183013 0.183013 0.683013 0.683013" mesh="bearing_5_16_5" material="bearing_5_16_5_material"/>
            <!-- Part hex_socket_head_cap_screw_m3x0_50_x_10__9c80fcbba574884e63b580474e1ee150_28 -->
            <!-- Part hex_socket_head_cap_screw_m4x0_70_x_40__14321d45d56569246e7feb4574a6bae6_28 -->
            <!-- Part hex_socket_head_cap_screw_m4x0_70_x_16__8d628c0d7a90368385b1c4c7479647eb_11 -->
            <!-- Part hex_socket_head_cap_screw_m2_5x0_45_x_6__ec244025d76f8b83b2775022a2cb3232_19 -->
            <!-- Part hex_socket_head_cap_screw_m4x0_70_x_8__a416dc2a8d778a4ef6150c0739aa89d1_23 -->
            <!-- Part hex_socket_head_cap_screw_m2_5x0_45_x_6__ec244025d76f8b83b2775022a2cb3232_20 -->
            <!-- Part hex_socket_head_cap_screw_m4x0_70_x_16__8d628c0d7a90368385b1c4c7479647eb_12 -->
            <!-- Part knee_actuation_2 -->
            <geom type="mesh" class="visual" pos="-0.058 0.123541 -0.0305" quat="0.707107 0.707107 3.33067e-16 1.45101e-15" mesh="knee_actuation" material="knee_actuation_material"/>
            <!-- Part femur_22_sym -->
            <geom type="mesh" class="visual" pos="-0.17 -0.294449 0.0295" quat="0.683013 -0.683013 0.183013 -0.183013" mesh="femur_22_sym" material="femur_22_sym_material"/>
            <!-- Part hat_femur_2 -->
            <geom type="mesh" class="visual" pos="-0.17 -0.294449 -0.0305" quat="0.183013 0.183013 0.683013 0.683013" mesh="hat_femur" material="hat_femur_material"/>
            <!-- Part hex_socket_head_cap_screw_m4x0_70_x_8__a416dc2a8d778a4ef6150c0739aa89d1_24 -->
            <!-- Part hex_socket_head_cap_screw_m3x0_50_x_10__9c80fcbba574884e63b580474e1ee150_29 -->
            <!-- Part bearing_5_16_5_6 -->
            <geom type="mesh" class="visual" pos="-0.17 -0.294449 -0.013" quat="0.183013 -0.183013 -0.683013 0.683013" mesh="bearing_5_16_5" material="bearing_5_16_5_material"/>
            <!-- Part robstrideo3_3 -->
            <geom type="mesh" class="visual" pos="0.655402 -0.194111 -0.0025" quat="0.183013 0.183013 0.683013 0.683013" mesh="robstrideo3" material="robstrideo3_material"/>
            <!-- Part hex_socket_head_cap_screw_m4x0_70_x_8__a416dc2a8d778a4ef6150c0739aa89d1_25 -->
            <!-- Part hex_socket_head_cap_screw_m4x0_70_x_8__a416dc2a8d778a4ef6150c0739aa89d1_26 -->
            <!-- Part hex_socket_head_cap_screw_m4x0_70_x_8__a416dc2a8d778a4ef6150c0739aa89d1_27 -->
            <!-- Part knee_rod12_sym -->
            <geom type="mesh" class="visual" pos="-0.058 -0.280519 0.0295" quat="0.707107 -0.707107 -1.77636e-15 5.57391e-16" mesh="knee_rod12_sym" material="knee_rod12_sym_material"/>
            <!-- Part hex_socket_head_cap_screw_m3x0_50_x_10__9c80fcbba574884e63b580474e1ee150_30 -->
            <!-- Part hex_socket_head_cap_screw_m2_5x0_45_x_6__ec244025d76f8b83b2775022a2cb3232_21 -->
            <!-- Part hex_socket_head_cap_screw_m4x0_70_x_8__a416dc2a8d778a4ef6150c0739aa89d1_28 -->
            <!-- Part robstrideo3_4 -->
            <geom type="mesh" class="visual" pos="0.597402 -0.29457 -0.045" quat="0.183013 0.183013 0.683013 0.683013" mesh="robstrideo3" material="robstrideo3_material"/>
            <!-- Part 1_1_31_qt_942_1_3 -->
            <geom type="mesh" class="visual" pos="-4.27436e-15 2.1233e-15 -0.04" quat="0.5 2.49471e-14 -9.54792e-15 -0.866025" mesh="1_1_31_qt_942_1" material="1_1_31_qt_942_1_material"/>
            <!-- Part 1_1_06_eb903_538_1_3 -->
            <geom type="mesh" class="visual" pos="-3.80251e-15 3.27516e-15 -0.0566" quat="0.5 2.49471e-14 -9.54792e-15 -0.866025" mesh="1_1_06_eb903_538_1" material="1_1_06_eb903_538_1_material"/>
            <!-- Part 1_1_31_qt_942_1_4 -->
            <geom type="mesh" class="visual" pos="-0.058 -0.100459 -0.0825" quat="0.965926 1.63358e-13 -5.85088e-14 -0.258819" mesh="1_1_31_qt_942_1" material="1_1_31_qt_942_1_material"/>
            <!-- Part 1_1_06_eb903_538_1_4 -->
            <geom type="mesh" class="visual" pos="-0.058 -0.100459 -0.0991" quat="0.965926 1.63358e-13 -5.85088e-14 -0.258819" mesh="1_1_06_eb903_538_1" material="1_1_06_eb903_538_1_material"/>
            <!-- Part 1_1_06_eb903_537_af0_1_3 -->
            <geom type="mesh" class="visual" pos="-3.60822e-15 1.59595e-15 -0.0375" quat="0.965926 3.30825e-14 -4.21885e-15 -0.258819" mesh="1_1_06_eb903_537_af0_1" material="1_1_06_eb903_537_af0_1_material"/>
            <!-- Part 1_1_02_eb901_558_1_3 -->
            <geom type="mesh" class="visual" pos="0 0 1.38778e-17" quat="0 1 0 0" mesh="1_1_02_eb901_558_1" material="1_1_02_eb901_558_1_material"/>
            <!-- Part 1_1_06_eb903_537_af0_1_4 -->
            <geom type="mesh" class="visual" pos="-0.058 -0.100459 -0.08" quat="0.866025 1.96549e-14 -2.73115e-14 0.5" mesh="1_1_06_eb903_537_af0_1" material="1_1_06_eb903_537_af0_1_material"/>
            <!-- Part 1_1_02_eb901_558_1_4 -->
            <geom type="mesh" class="visual" pos="-0.058 -0.100459 -0.0425" quat="1.2217e-14 -0.707107 -0.707107 -1.32445e-14" mesh="1_1_02_eb901_558_1" material="1_1_02_eb901_558_1_material"/>
            <!-- Link shin_subassembly_sym -->
            <body name="shin_subassembly_sym" pos="-0.17 -0.294449 -0.0305" quat="0.723237 3.153e-14 1.17684e-14 -0.6906">
              <!-- Joint from tigh_subassembly_sym to shin_subassembly_sym -->
              <joint axis="0 0 1" name="knee_left" type="hinge"/>
              <inertial pos="0.00141118 -0.0907865 -1.51262e-05" mass="0.593266" fullinertia="0.00173329 0.000245102 0.00175808 -5.71341e-05 3.03885e-06 9.30277e-05"/>
              <!-- Part hex_socket_head_cap_screw_m3x0_50_x_20__7252065e4445f5ec71347b53fcae11e4_13 -->
              <!-- Part xt_30_2x2_f_6 -->
              <geom type="mesh" class="visual" pos="0.0212074 -0.0322876 0.0147" quat="0.270598 0.653281 0.270598 -0.653281" mesh="xt_30_2x2_f" material="xt_30_2x2_f_material"/>
              <!-- Part hex_socket_head_cap_screw_m3x0_50_x_20__7252065e4445f5ec71347b53fcae11e4_14 -->
              <!-- Part hex_socket_head_cap_screw_m3x0_50_x_20__7252065e4445f5ec71347b53fcae11e4_15 -->
              <!-- Part hex_socket_head_cap_screw_m3x0_50_x_10__9c80fcbba574884e63b580474e1ee150_31 -->
              <!-- Part 27628_01_050_catpart_5 -->
              <geom type="mesh" class="visual" pos="0.0300907 -0.0130682 -0.0195" quat="0.695189 0.695189 0.129277 0.129277" mesh="27628_01_050_catpart" material="27628_01_050_catpart_material"/>
              <!-- Part hex_socket_head_cap_screw_m3x0_50_x_20__7252065e4445f5ec71347b53fcae11e4_16 -->
              <!-- Part hex_socket_head_cap_screw_m3x0_50_x_30__cb22dc4460edbee8e1cbddf29677c00f_2 -->
              <!-- Part hex_socket_head_cap_screw_m3x0_50_x_10__9c80fcbba574884e63b580474e1ee150_32 -->
              <!-- Part hex_socket_head_cap_screw_m3x0_50_x_10__9c80fcbba574884e63b580474e1ee150_33 -->
              <!-- Part 07534_05x40_catpart_3 -->
              <geom type="mesh" class="visual" pos="5.55112e-17 0 -0.025" quat="0.5 -0.5 -0.5 -0.5" mesh="07534_05x40_catpart" material="07534_05x40_catpart_material"/>
              <!-- Part hex_socket_head_cap_screw_m3x0_50_x_10__9c80fcbba574884e63b580474e1ee150_34 -->
              <!-- Part hex_socket_head_cap_screw_m3x0_50_x_10__9c80fcbba574884e63b580474e1ee150_35 -->
              <!-- Part hex_socket_head_cap_screw_m3x0_50_x_10__9c80fcbba574884e63b580474e1ee150_36 -->
              <!-- Part hex_socket_head_cap_screw_m3x0_50_x_10__9c80fcbba574884e63b580474e1ee150_37 -->
              <!-- Part hex_socket_head_cap_screw_m3x0_50_x_20__7252065e4445f5ec71347b53fcae11e4_17 -->
              <!-- Part 07534_05x20_catpart_5 -->
              <geom type="mesh" class="visual" pos="0.0300908 -0.0660682 0.0405" quat="0.632814 -0.315509 0.632814 0.315509" mesh="07534_05x20_catpart" material="07534_05x20_catpart_material"/>
              <!-- Part tibias12_sym -->
              <geom type="mesh" class="visual" pos="-2.77556e-16 -0.26 0.067" quat="0.707107 -0.707107 3.33067e-16 -3.82186e-18" mesh="tibias12_sym" material="tibias12_sym_material"/>
              <!-- Part hex_socket_head_cap_screw_m2_5x0_45_x_8__dec2226ceabd7d7ca0bb403ec234d89b_4 -->
              <!-- Part actuation_ankle_3 -->
              <geom type="mesh" class="visual" pos="0.12299 -0.14568 0.0195" quat="0.632814 -0.632814 -0.315509 0.315509" mesh="actuation_ankle" material="actuation_ankle_material"/>
              <!-- Part hex_socket_head_cap_screw_m3x0_50_x_20__7252065e4445f5ec71347b53fcae11e4_18 -->
              <!-- Part hex_socket_head_cap_screw_m3x0_50_x_10__9c80fcbba574884e63b580474e1ee150_38 -->
              <!-- Part hex_socket_head_cap_screw_m3x0_50_x_10__9c80fcbba574884e63b580474e1ee150_39 -->
              <!-- Part hex_thin_nut_grade_a___b_m4x0_7__a8228d9ce5dcc05f24da0a2f74d882f3_5 -->
              <geom type="mesh" class="visual" pos="0.0300908 -0.0660682 0.0129398" quat="5.28185e-16 0.317305 0.948324 6.50841e-16" mesh="hex_thin_nut_grade_a___b_m4x0_7__a8228d9ce5dcc05f24da0a2f74d882f3" material="hex_thin_nut_grade_a___b_m4x0_7__a8228d9ce5dcc05f24da0a2f74d882f3_material"/>
              <!-- Part hex_socket_head_cap_screw_m3x0_50_x_10__9c80fcbba574884e63b580474e1ee150_40 -->
              <!-- Part hex_socket_head_cap_screw_m3x0_50_x_20__7252065e4445f5ec71347b53fcae11e4_19 -->
              <!-- Part hex_socket_head_cap_screw_m3x0_50_x_20__7252065e4445f5ec71347b53fcae11e4_20 -->
              <!-- Part hex_socket_head_cap_screw_m3x0_50_x_10__9c80fcbba574884e63b580474e1ee150_41 -->
              <!-- Part rmdx43_3 -->
              <geom type="mesh" class="visual" pos="0.470217 -0.113201 -0.006" quat="3.33067e-16 -5.29747e-16 -0.707107 0.707107" mesh="rmdx43" material="rmdx43_material"/>
              <!-- Part hex_socket_head_cap_screw_m2_5x0_45_x_8__dec2226ceabd7d7ca0bb403ec234d89b_5 -->
              <!-- Part hex_socket_head_cap_screw_m4x0_70_x_12__c825518ee8edf1afced0eee1b019b750_17 -->
              <!-- Part hex_socket_head_cap_screw_m3x0_50_x_20__7252065e4445f5ec71347b53fcae11e4_21 -->
              <!-- Part hex_socket_head_cap_screw_m4x0_70_x_12__c825518ee8edf1afced0eee1b019b750_18 -->
              <!-- Part hex_socket_head_cap_screw_m3x0_50_x_10__9c80fcbba574884e63b580474e1ee150_42 -->
              <!-- Part hex_socket_head_cap_screw_m3x0_50_x_10__9c80fcbba574884e63b580474e1ee150_43 -->
              <!-- Part hex_socket_head_cap_screw_m3x0_50_x_10__9c80fcbba574884e63b580474e1ee150_44 -->
              <!-- Part hex_socket_head_cap_screw_m4x0_70_x_12__c825518ee8edf1afced0eee1b019b750_19 -->
              <!-- Part hex_socket_head_cap_screw_m3x0_50_x_20__7252065e4445f5ec71347b53fcae11e4_22 -->
              <!-- Part hex_socket_head_cap_screw_m3x0_50_x_10__9c80fcbba574884e63b580474e1ee150_45 -->
              <!-- Part hex_socket_head_cap_screw_m3x0_50_x_10__9c80fcbba574884e63b580474e1ee150_46 -->
              <!-- Part 07534_05x20_catpart_6 -->
              <geom type="mesh" class="visual" pos="0.0300908 -0.0130682 -0.0405" quat="0.632814 0.315509 -0.632814 0.315509" mesh="07534_05x20_catpart" material="07534_05x20_catpart_material"/>
              <!-- Part rmdx43_4 -->
              <geom type="mesh" class="visual" pos="0.470217 -0.0457991 0.006" quat="3.33067e-16 -8.33994e-16 -0.707107 -0.707107" mesh="rmdx43" material="rmdx43_material"/>
              <!-- Part tibias22_sym -->
              <geom type="mesh" class="visual" pos="-6.66134e-16 -0.26 0.067" quat="0.707107 -0.707107 2.22045e-16 -4.79557e-16" mesh="tibias22_sym" material="tibias22_sym_material"/>
              <!-- Part hex_socket_head_cap_screw_m3x0_50_x_20__7252065e4445f5ec71347b53fcae11e4_23 -->
              <!-- Part hex_socket_head_cap_screw_m4x0_70_x_12__c825518ee8edf1afced0eee1b019b750_20 -->
              <!-- Part hex_socket_head_cap_screw_m3x0_50_x_10__9c80fcbba574884e63b580474e1ee150_47 -->
              <!-- Part xt_30_2x2_f_7 -->
              <geom type="mesh" class="visual" pos="0.0212074 -0.126712 -0.015" quat="0.653281 -0.270598 -0.653281 -0.270598" mesh="xt_30_2x2_f" material="xt_30_2x2_f_material"/>
              <!-- Part hex_thin_nut_grade_a___b_m4x0_7__a8228d9ce5dcc05f24da0a2f74d882f3_6 -->
              <geom type="mesh" class="visual" pos="5.55112e-17 0 0.0247602" quat="8.88178e-16 -3.19496e-16 1 -2.9976e-15" mesh="hex_thin_nut_grade_a___b_m4x0_7__a8228d9ce5dcc05f24da0a2f74d882f3" material="hex_thin_nut_grade_a___b_m4x0_7__a8228d9ce5dcc05f24da0a2f74d882f3_material"/>
              <!-- Part hex_socket_head_cap_screw_m3x0_50_x_10__9c80fcbba574884e63b580474e1ee150_48 -->
              <!-- Part hex_socket_head_cap_screw_m3x0_50_x_10__9c80fcbba574884e63b580474e1ee150_49 -->
              <!-- Part actuation_ankle_4 -->
              <geom type="mesh" class="visual" pos="-0.12299 -0.0133205 -0.0195" quat="0.632814 0.632814 0.315509 0.315509" mesh="actuation_ankle" material="actuation_ankle_material"/>
              <!-- Part hex_socket_head_cap_screw_m3x0_50_x_10__9c80fcbba574884e63b580474e1ee150_50 -->
              <!-- Part hex_socket_head_cap_screw_m3x0_50_x_10__9c80fcbba574884e63b580474e1ee150_51 -->
              <!-- Part hex_socket_head_cap_screw_m3x0_50_x_10__9c80fcbba574884e63b580474e1ee150_52 -->
              <!-- Part hex_socket_head_cap_screw_m3x0_50_x_10__9c80fcbba574884e63b580474e1ee150_53 -->
              <!-- Part hex_socket_head_cap_screw_m3x0_50_x_20__7252065e4445f5ec71347b53fcae11e4_24 -->
              <!-- Part hat_big_2 -->
              <geom type="mesh" class="visual" pos="-3.88578e-16 -0.26 -0.019" quat="3.33067e-16 2.11269e-16 0.707107 0.707107" mesh="hat_big" material="hat_big_material"/>
              <!-- Part hex_socket_head_cap_screw_m2_5x0_45_x_8__dec2226ceabd7d7ca0bb403ec234d89b_6 -->
              <!-- Part 27628_01_050_catpart_6 -->
              <geom type="mesh" class="visual" pos="0.0300908 -0.066068 0.0225" quat="0.154305 0.154305 0.690065 0.690065" mesh="27628_01_050_catpart" material="27628_01_050_catpart_material"/>
              <!-- Part hex_socket_head_cap_screw_m3x0_50_x_10__9c80fcbba574884e63b580474e1ee150_54 -->
              <!-- Part hex_thin_nut_grade_a___b_m4x0_7__a8228d9ce5dcc05f24da0a2f74d882f3_7 -->
              <geom type="mesh" class="visual" pos="0.0300908 -0.0130682 -0.0129398" quat="0.317305 4.3979e-16 2.84217e-14 0.948324" mesh="hex_thin_nut_grade_a___b_m4x0_7__a8228d9ce5dcc05f24da0a2f74d882f3" material="hex_thin_nut_grade_a___b_m4x0_7__a8228d9ce5dcc05f24da0a2f74d882f3_material"/>
              <!-- Part 1_1_31_eb463_510_fl46blw10_48v_5n_m_de_2__fl46blw10_48v_5n_m_de_3 -->
              <geom type="mesh" class="visual" pos="-3.83027e-15 -0.106 0.019" quat="0.19509 -4.57367e-14 7.36078e-14 0.980785" mesh="1_1_31_eb463_510_fl46blw10_48v_5n_m_de_2__fl46blw10_48v_5n_m_de" material="1_1_31_eb463_510_fl46blw10_48v_5n_m_de_2__fl46blw10_48v_5n_m_de_material"/>
              <!-- Part 1_1_02_eb461_502_fl46blw10_48v_5n_m_de_2__fl46blw10_48v_5n_m_de_3 -->
              <geom type="mesh" class="visual" pos="-2.05391e-15 -0.106 0.009" quat="0.19509 -4.57367e-14 7.36078e-14 0.980785" mesh="1_1_02_eb461_502_fl46blw10_48v_5n_m_de_2__fl46blw10_48v_5n_m_de" material="1_1_02_eb461_502_fl46blw10_48v_5n_m_de_2__fl46blw10_48v_5n_m_de_material"/>
              <!-- Part 1_1_06_eb463_509_fl46blw10_48v_5n_m_de_2__fl46blw10_48v_5n_m_de_3 -->
              <geom type="mesh" class="visual" pos="-1.66533e-16 -0.106 -0.0225" quat="0.707107 0 8.23994e-16 0.707107" mesh="1_1_06_eb463_509_fl46blw10_48v_5n_m_de_2__fl46blw10_48v_5n_m_de" material="1_1_06_eb463_509_fl46blw10_48v_5n_m_de_2__fl46blw10_48v_5n_m_de_material"/>
              <!-- Part 1_1_06_eb463_507_fl46blw10_48v_5n_m_de_2__fl46blw10_48v_5n_m_de_3 -->
              <geom type="mesh" class="visual" pos="-1.33227e-15 -0.106 -0.009" quat="0.382683 -4.80041e-14 5.973e-14 0.92388" mesh="1_1_06_eb463_507_fl46blw10_48v_5n_m_de_2__fl46blw10_48v_5n_m_de" material="1_1_06_eb463_507_fl46blw10_48v_5n_m_de_2__fl46blw10_48v_5n_m_de_material"/>
              <!-- Part 1_1_31_eb463_510_fl46blw10_48v_5n_m_de_2__fl46blw10_48v_5n_m_de_4 -->
              <geom type="mesh" class="visual" pos="2.22045e-16 -0.053 -0.019" quat="1.02403e-14 0.19509 -0.980785 1.32091e-13" mesh="1_1_31_eb463_510_fl46blw10_48v_5n_m_de_2__fl46blw10_48v_5n_m_de" material="1_1_31_eb463_510_fl46blw10_48v_5n_m_de_2__fl46blw10_48v_5n_m_de_material"/>
              <!-- Part 1_1_02_eb461_502_fl46blw10_48v_5n_m_de_2__fl46blw10_48v_5n_m_de_4 -->
              <geom type="mesh" class="visual" pos="1.33227e-15 -0.053 -0.009" quat="1.02403e-14 0.19509 -0.980785 1.32091e-13" mesh="1_1_02_eb461_502_fl46blw10_48v_5n_m_de_2__fl46blw10_48v_5n_m_de" material="1_1_02_eb461_502_fl46blw10_48v_5n_m_de_2__fl46blw10_48v_5n_m_de_material"/>
              <!-- Part 1_1_06_eb463_509_fl46blw10_48v_5n_m_de_2__fl46blw10_48v_5n_m_de_4 -->
              <geom type="mesh" class="visual" pos="0 -0.053 0.0225" quat="2.40309e-16 0.707107 -0.707107 5.07715e-16" mesh="1_1_06_eb463_509_fl46blw10_48v_5n_m_de_2__fl46blw10_48v_5n_m_de" material="1_1_06_eb463_509_fl46blw10_48v_5n_m_de_2__fl46blw10_48v_5n_m_de_material"/>
              <!-- Part 1_1_06_eb463_507_fl46blw10_48v_5n_m_de_2__fl46blw10_48v_5n_m_de_4 -->
              <geom type="mesh" class="visual" pos="-2.77556e-16 -0.053 0.009" quat="3.25561e-14 0.382683 -0.92388 1.27549e-13" mesh="1_1_06_eb463_507_fl46blw10_48v_5n_m_de_2__fl46blw10_48v_5n_m_de" material="1_1_06_eb463_507_fl46blw10_48v_5n_m_de_2__fl46blw10_48v_5n_m_de_material"/>
              <!-- Part 0001755652_1_1_30_gr_2202_asm_1_asm_1_1_30_gr_2202_asm_fl46blw10_48v_5n_m_de_2__fl46blw10_48v_5n_m_de_5 -->
              <geom type="mesh" class="visual" pos="0.00671751 -0.0992825 0.0235" quat="6.03493e-14 0.92388 -0.382683 4.75134e-14" mesh="0001755652_1_1_30_gr_2202_asm_1_asm_1_1_30_gr_2202_asm_fl46blw10_48v_5n_m_de_2__fl46blw10_48v_5n_m_de" material="0001755652_1_1_30_gr_2202_asm_1_asm_1_1_30_gr_2202_asm_fl46blw10_48v_5n_m_de_2__fl46blw10_48v_5n_m_de_material"/>
              <!-- Part 0001755652_1_1_30_gr_2202_asm_1_asm_1_1_30_gr_2202_asm_fl46blw10_48v_5n_m_de_2__fl46blw10_48v_5n_m_de_6 -->
              <geom type="mesh" class="visual" pos="0.00245878 -0.115176 0.0235" quat="6.03493e-14 0.92388 -0.382683 4.75134e-14" mesh="0001755652_1_1_30_gr_2202_asm_1_asm_1_1_30_gr_2202_asm_fl46blw10_48v_5n_m_de_2__fl46blw10_48v_5n_m_de" material="0001755652_1_1_30_gr_2202_asm_1_asm_1_1_30_gr_2202_asm_fl46blw10_48v_5n_m_de_2__fl46blw10_48v_5n_m_de_material"/>
              <!-- Part 0001755652_1_1_30_gr_2202_asm_1_asm_1_1_30_gr_2202_asm_fl46blw10_48v_5n_m_de_2__fl46blw10_48v_5n_m_de_7 -->
              <geom type="mesh" class="visual" pos="0.00671751 -0.0597175 -0.0235" quat="0.92388 -2.03715e-14 1.96509e-14 0.382683" mesh="0001755652_1_1_30_gr_2202_asm_1_asm_1_1_30_gr_2202_asm_fl46blw10_48v_5n_m_de_2__fl46blw10_48v_5n_m_de" material="0001755652_1_1_30_gr_2202_asm_1_asm_1_1_30_gr_2202_asm_fl46blw10_48v_5n_m_de_2__fl46blw10_48v_5n_m_de_material"/>
              <!-- Part 0001755652_1_1_30_gr_2202_asm_1_asm_1_1_30_gr_2202_asm_fl46blw10_48v_5n_m_de_2__fl46blw10_48v_5n_m_de_8 -->
              <geom type="mesh" class="visual" pos="0.00245878 -0.0438237 -0.0235" quat="0.92388 -2.03715e-14 1.96509e-14 0.382683" mesh="0001755652_1_1_30_gr_2202_asm_1_asm_1_1_30_gr_2202_asm_fl46blw10_48v_5n_m_de_2__fl46blw10_48v_5n_m_de" material="0001755652_1_1_30_gr_2202_asm_1_asm_1_1_30_gr_2202_asm_fl46blw10_48v_5n_m_de_2__fl46blw10_48v_5n_m_de_material"/>
              <!-- Part 0001755652_00mini_000_asm_1_asm_1_asm_00mini__20250103_a0001_asm_1_as_asm_1_1_30_gr_2202_asm_1_asm_1_1_30_gr_2202_asm_fl46blw10_48v_5n_m_de_2__fl46blw10_48v_5n_m_de_3 -->
              <geom type="mesh" class="visual" pos="-0.0091763 -0.103541 0.0235" quat="6.03493e-14 0.92388 -0.382683 4.75134e-14" mesh="0001755652_00mini_000_asm_1_asm_1_asm_00mini__20250103_a0001_asm_1_as_asm_1_1_30_gr_2202_asm_1_asm_1_1_30_gr_2202_asm_fl46blw10_48v_5n_m_de_2__fl46blw10_48v_5n_m_de" material="0001755652_00mini_000_asm_1_asm_1_asm_00mini__20250103_a0001_asm_1_as_asm_1_1_30_gr_2202_asm_1_asm_1_1_30_gr_2202_asm_fl46blw10_48v_5n_m_de_2__fl46blw10_48v_5n_m_de_material"/>
              <!-- Part 6706__300001_1_1_00mini_000_asm_1_asm_1_asm_00mini__20250103_a0001_asm_1_as_asm_1_1_30_gr_2202_asm_1_asm_1_1_30_gr_2202_asm_fl46blw10_48v_5n_m_de_2__fl46blw10_48v_5n_m_de_3 -->
              <geom type="mesh" class="visual" pos="-3.44169e-15 -0.106 0.02" quat="6.03493e-14 0.92388 -0.382683 4.75134e-14" mesh="6706__300001_1_1_00mini_000_asm_1_asm_1_asm_00mini__20250103_a0001_asm_1_as_asm_1_1_30_gr_2202_asm_1_asm_1_1_30_gr_2202_asm_fl46blw10_48v_5n_m_de_2__fl46blw10_48v_5n_m_de" material="6706__300001_1_1_00mini_000_asm_1_asm_1_asm_00mini__20250103_a0001_asm_1_as_asm_1_1_30_gr_2202_asm_1_asm_1_1_30_gr_2202_asm_fl46blw10_48v_5n_m_de_2__fl46blw10_48v_5n_m_de_material"/>
              <!-- Part 0001755650_00mini_000_asm_1_asm_1_asm_00mini__20250103_a0001_asm_1_as_asm_1_1_30_gr_2202_asm_1_asm_1_1_30_gr_2202_asm_fl46blw10_48v_5n_m_de_2__fl46blw10_48v_5n_m_de_3 -->
              <geom type="mesh" class="visual" pos="-3.38618e-15 -0.106 0.0204" quat="6.03493e-14 0.92388 -0.382683 4.75134e-14" mesh="0001755650_00mini_000_asm_1_asm_1_asm_00mini__20250103_a0001_asm_1_as_asm_1_1_30_gr_2202_asm_1_asm_1_1_30_gr_2202_asm_fl46blw10_48v_5n_m_de_2__fl46blw10_48v_5n_m_de" material="0001755650_00mini_000_asm_1_asm_1_asm_00mini__20250103_a0001_asm_1_as_asm_1_1_30_gr_2202_asm_1_asm_1_1_30_gr_2202_asm_fl46blw10_48v_5n_m_de_2__fl46blw10_48v_5n_m_de_material"/>
              <!-- Part 0001755652_00mini_000_asm_1_asm_1_asm_00mini__20250103_a0001_asm_1_as_asm_1_1_30_gr_2202_asm_1_asm_1_1_30_gr_2202_asm_fl46blw10_48v_5n_m_de_2__fl46blw10_48v_5n_m_de_4 -->
              <geom type="mesh" class="visual" pos="-0.0091763 -0.0554588 -0.0235" quat="0.92388 -2.03715e-14 1.96509e-14 0.382683" mesh="0001755652_00mini_000_asm_1_asm_1_asm_00mini__20250103_a0001_asm_1_as_asm_1_1_30_gr_2202_asm_1_asm_1_1_30_gr_2202_asm_fl46blw10_48v_5n_m_de_2__fl46blw10_48v_5n_m_de" material="0001755652_00mini_000_asm_1_asm_1_asm_00mini__20250103_a0001_asm_1_as_asm_1_1_30_gr_2202_asm_1_asm_1_1_30_gr_2202_asm_fl46blw10_48v_5n_m_de_2__fl46blw10_48v_5n_m_de_material"/>
              <!-- Part 6706__300001_1_1_00mini_000_asm_1_asm_1_asm_00mini__20250103_a0001_asm_1_as_asm_1_1_30_gr_2202_asm_1_asm_1_1_30_gr_2202_asm_fl46blw10_48v_5n_m_de_2__fl46blw10_48v_5n_m_de_4 -->
              <geom type="mesh" class="visual" pos="1.60982e-15 -0.053 -0.02" quat="0.92388 -2.03715e-14 1.96509e-14 0.382683" mesh="6706__300001_1_1_00mini_000_asm_1_asm_1_asm_00mini__20250103_a0001_asm_1_as_asm_1_1_30_gr_2202_asm_1_asm_1_1_30_gr_2202_asm_fl46blw10_48v_5n_m_de_2__fl46blw10_48v_5n_m_de" material="6706__300001_1_1_00mini_000_asm_1_asm_1_asm_00mini__20250103_a0001_asm_1_as_asm_1_1_30_gr_2202_asm_1_asm_1_1_30_gr_2202_asm_fl46blw10_48v_5n_m_de_2__fl46blw10_48v_5n_m_de_material"/>
              <!-- Part 0001755650_00mini_000_asm_1_asm_1_asm_00mini__20250103_a0001_asm_1_as_asm_1_1_30_gr_2202_asm_1_asm_1_1_30_gr_2202_asm_fl46blw10_48v_5n_m_de_2__fl46blw10_48v_5n_m_de_4 -->
              <geom type="mesh" class="visual" pos="1.11022e-15 -0.053 -0.0204" quat="0.92388 -2.03715e-14 1.96509e-14 0.382683" mesh="0001755650_00mini_000_asm_1_asm_1_asm_00mini__20250103_a0001_asm_1_as_asm_1_1_30_gr_2202_asm_1_asm_1_1_30_gr_2202_asm_fl46blw10_48v_5n_m_de_2__fl46blw10_48v_5n_m_de" material="0001755650_00mini_000_asm_1_asm_1_asm_00mini__20250103_a0001_asm_1_as_asm_1_1_30_gr_2202_asm_1_asm_1_1_30_gr_2202_asm_fl46blw10_48v_5n_m_de_2__fl46blw10_48v_5n_m_de_material"/>
              <!-- Link ankle_subassembly_2 -->
              <body name="ankle_subassembly_2" pos="-4.44089e-16 -0.26 -0.02" quat="0.888101 -7.37179e-16 1.11022e-16 -0.459649">
                <!-- Joint from shin_subassembly_sym to ankle_subassembly_2 -->
                <joint axis="0 0 1" name="ankley_left" type="hinge"/>
                <inertial pos="1.62086e-08 -0.000727483 0.02" mass="0.0168168" fullinertia="5.19458e-06 4.86353e-06 8.35665e-07 -2.61119e-12 4.35145e-12 7.24871e-13"/>
                <!-- Part hex_socket_head_cap_screw_m2_5x0_45_x_6__ec244025d76f8b83b2775022a2cb3232_22 -->
                <!-- Part 07534_05x40_catpart_4 -->
                <geom type="mesh" class="visual" pos="-6.10623e-15 0.0249999 0.02" quat="0.707107 8.42021e-14 -6.30607e-14 -0.707107" mesh="07534_05x40_catpart" material="07534_05x40_catpart_material"/>
                <!-- Part ujoint_2 -->
                <geom type="mesh" class="visual" pos="-2.22045e-15 -4.64212e-15 0.02" quat="3.80815e-14 -0.707107 -7.20535e-14 -0.707107" mesh="ujoint" material="ujoint_material"/>
                <!-- Part hex_socket_head_cap_screw_m2_5x0_45_x_6__ec244025d76f8b83b2775022a2cb3232_23 -->
                <!-- Part spacer_ujoint_3 -->
                <geom type="mesh" class="visual" pos="-1.22125e-15 -6.89032e-15 0.02" quat="0.699514 -5.29311e-14 0.714619 5.09987e-14" mesh="spacer_ujoint" material="spacer_ujoint_material"/>
                <!-- Part hex_thin_nut_grade_a___b_m4x0_7__a8228d9ce5dcc05f24da0a2f74d882f3_8 -->
                <geom type="mesh" class="visual" pos="-2.39808e-14 -0.02204 0.02" quat="0.494631 -0.494631 0.505312 0.505312" mesh="hex_thin_nut_grade_a___b_m4x0_7__a8228d9ce5dcc05f24da0a2f74d882f3" material="hex_thin_nut_grade_a___b_m4x0_7__a8228d9ce5dcc05f24da0a2f74d882f3_material"/>
                <!-- Part part_3_5 -->
                <geom type="mesh" class="visual" pos="6.66134e-16 -6.11663e-15 0.0205" quat="3.84213e-14 -0.707107 -7.21645e-14 -0.707107" mesh="part_3" material="part_3_material"/>
                <!-- Part bearing_5_16_5_7 -->
                <geom type="mesh" class="visual" pos="7.54952e-15 -0.01594 0.02" quat="0.699514 -5.26424e-14 0.714619 5.29268e-14" mesh="bearing_5_16_5" material="bearing_5_16_5_material"/>
                <!-- Part bearing_15_21_4_13 -->
                <geom type="mesh" class="visual" pos="-2.33147e-15 -8.62158e-15 0.04" quat="3.60822e-16 -1.30987e-15 0.707107 -0.707107" mesh="bearing_15_21_4" material="bearing_15_21_4_material"/>
                <!-- Part hex_socket_head_cap_screw_m2_5x0_45_x_6__ec244025d76f8b83b2775022a2cb3232_24 -->
                <!-- Part hex_socket_head_cap_screw_m2_5x0_45_x_6__ec244025d76f8b83b2775022a2cb3232_25 -->
                <!-- Part part_3_6 -->
                <geom type="mesh" class="visual" pos="-3.9968e-15 -2.2829e-15 0.0195" quat="5.01886e-14 0.707107 5.31797e-14 -0.707107" mesh="part_3" material="part_3_material"/>
                <!-- Part hex_socket_head_cap_screw_m2_5x0_45_x_6__ec244025d76f8b83b2775022a2cb3232_26 -->
                <!-- Part hex_socket_head_cap_screw_m2_5x0_45_x_6__ec244025d76f8b83b2775022a2cb3232_27 -->
                <!-- Part bearing_5_16_5_8 -->
                <geom type="mesh" class="visual" pos="2.9976e-15 0.0209456 0.02" quat="0.999973 -2.00638e-14 -0.00732917 6.31413e-14" mesh="bearing_5_16_5" material="bearing_5_16_5_material"/>
                <!-- Part spacer_ujoint_4 -->
                <geom type="mesh" class="visual" pos="3.77476e-15 5.64895e-06 0.02" quat="3.99894e-14 -0.701905 -7.31637e-14 -0.71227" mesh="spacer_ujoint" material="spacer_ujoint_material"/>
                <!-- Part bearing_15_21_4_14 -->
                <geom type="mesh" class="visual" pos="0 0 0" quat="0.707107 0.707107 0 3.44812e-31" mesh="bearing_15_21_4" material="bearing_15_21_4_material"/>
                <!-- Link foot_subassembly_2 -->
                <body name="foot_subassembly_2" pos="7.54952e-15 -0.01594 0.02" quat="0.5 0.5 -0.5 0.5">
                  <!-- Joint from ankle_subassembly_2 to foot_subassembly_2 -->
                  <joint axis="0 0 1" name="anklex_left" type="hinge"/>
                  <inertial pos="8.52312e-09 -0.0138418 -0.052232" mass="0.122498" fullinertia="0.000163413 0.000162266 7.07692e-05 -1.15065e-10 -2.96383e-11 1.11374e-05"/>
                  <!-- Part hex_socket_head_cap_screw_m2_5x0_45_x_6__ec244025d76f8b83b2775022a2cb3232_28 -->
                  <!-- Part 27628_01_050_catpart_7 -->
                  <geom type="mesh" class="visual" pos="0.021 3.53792e-08 -0.0660002" quat="3.65645e-17 -0.707107 -0.707107 -9.5443e-17" mesh="27628_01_050_catpart" material="27628_01_050_catpart_material"/>
                  <!-- Part hex_socket_head_cap_screw_m2_5x0_45_x_6__ec244025d76f8b83b2775022a2cb3232_29 -->
                  <!-- Part 07534_05x20_catpart_7 -->
                  <geom type="mesh" class="visual" pos="0.036 0 -0.066" quat="0 -3.8223e-16 -1 -6.38378e-16" mesh="07534_05x20_catpart" material="07534_05x20_catpart_material"/>
                  <!-- Part 27628_01_050_catpart_8 -->
                  <geom type="mesh" class="visual" pos="-0.021 -1.89504e-08 -0.066" quat="4.86309e-16 -0.707107 -0.707107 -4.86309e-16" mesh="27628_01_050_catpart" material="27628_01_050_catpart_material"/>
                  <!-- Part 07534_05x20_catpart_8 -->
                  <geom type="mesh" class="visual" pos="-0.036 0 -0.066" quat="1 -2.45256e-18 6.93889e-17 7.1991e-17" mesh="07534_05x20_catpart" material="07534_05x20_catpart_material"/>
                  <!-- Part hat_small_2 -->
                  <geom type="mesh" class="visual" pos="2.35922e-16 -0.035 -0.0385" quat="0.5 -0.5 -0.5 -0.5" mesh="hat_small" material="hat_small_material"/>
                  <!-- Part hex_socket_head_cap_screw_m2_5x0_45_x_6__ec244025d76f8b83b2775022a2cb3232_30 -->
                  <!-- Part foot_2 -->
                  <geom type="mesh" class="visual" pos="1.11022e-16 -0.035 -0.0385" quat="0.5 -0.5 -0.5 -0.5" mesh="foot" material="foot_material"/>
                  <geom name="left_foot1_collision" class="collision" type="capsule" size="0.015 0.05" fromto="-0.032 -0.02 0.005 0.032 -0.02 0.005"/>
                  <geom name="left_foot2_collision" class="collision" type="capsule" size="0.015 0.05" fromto="-0.032 -0.02 -0.10 0.032 -0.02 -0.10"/>
                  <geom name="left_foot3_collision" class="collision" type="capsule" size="0.015 0.05" fromto="-0.032 -0.02 0.005 -0.032 -0.02 -0.10"/>
                  <geom name="left_foot4_collision" class="collision" type="capsule" size="0.015 0.05" fromto="0.032 -0.02 0.005 0.032 -0.02 -0.10"/>
                  <geom name="left_foot5_collision" class="collision" type="capsule" size="0.015 0.05" fromto="-0.032 -0.02 -0.02 0.032 -0.02 -0.02"/>
                  <geom name="left_foot6_collision" class="collision" type="capsule" size="0.015 0.05" fromto="-0.032 -0.02 -0.06 0.032 -0.02 -0.06"/>
                  <!-- Frame foot_left -->
                  <site group="3" name="foot_left" pos="-6.35351e-08 -0.035 -0.0480606" quat="0.5 -0.5 0.5 0.5"/>
                </body>
              </body>
            </body>
          </body>
        </body>
      </body>
      <!-- Link torso_subassembly_2 -->
      <body name="torso_subassembly_2" pos="-0.0255428 4.05842e-07 0.036034" quat="1.31899e-16 1 -5.69206e-19 4.80489e-18">
        <!-- Joint from torso_subassembly to torso_subassembly_2 -->
        <!-- Joint is "fixed", skipping it -->
        <inertial pos="-0.0016543 7.11966e-08 -0.15917" mass="2.64598" fullinertia="0.0262387 0.0163605 0.0108077 3.33924e-09 -0.000256171 8.14425e-09"/>
        <!-- Part torso_pperbody_part -->
        <geom type="mesh" class="visual" pos="-3.46945e-18 5.29396e-23 0" quat="0 1 0 0" mesh="torso_pperbody_part" material="torso_pperbody_part_material"/>
        <!-- Part robstrideo0_3 -->
        <geom type="mesh" class="visual" pos="-0.491975 -0.221542 0.0994842" quat="0.349577 0.863281 0.337447 -0.136646" mesh="robstrideo0" material="robstrideo0_material"/>
        <!-- Part rs00_3 -->
        <!-- Part bearing_holder_upperbody -->
        <geom type="mesh" class="visual" pos="-0.132416 -0.177102 -0.290974" quat="0.95241 -0.295367 -0.0660852 0.0361506" mesh="bearing_holder_upperbody" material="bearing_holder_upperbody_material"/>
        <!-- Part bearing_holder_upperbody_2 -->
        <geom type="mesh" class="visual" pos="-0.116047 0.20345 -0.285486" quat="0.86686 -0.115458 0.0919179 -0.476209" mesh="bearing_holder_upperbody" material="bearing_holder_upperbody_material"/>
        <!-- Part rs00_4 -->
        <!-- Part robstrideo0_4 -->
        <geom type="mesh" class="visual" pos="-0.491975 0.236796 0.0837372" quat="0.863281 0.349577 0.136646 -0.337447" mesh="robstrideo0" material="robstrideo0_material"/>
        <!-- Link shoulder1_subassembly -->
        <body name="shoulder1_subassembly" pos="-0.00401992 0.10362 -0.230772" quat="0.126652 0.526276 -0.691886 -0.477794">
          <!-- Joint from torso_subassembly_2 to shoulder1_subassembly -->
          <joint axis="0 0 1" name="shoulder1_right" type="hinge"/>
          <inertial pos="-0.00416441 0.00450914 -0.0453884" mass="0.0533612" fullinertia="3.8204e-05 3.76594e-05 1.45394e-05 3.3665e-06 -4.64098e-06 4.9903e-06"/>
          <!-- Part shoulder1_part -->
          <geom type="mesh" class="visual" pos="0.000329193 0.000172647 -0.0246" quat="1 1.5786e-14 4.996e-15 6.50521e-18" mesh="shoulder1_part" material="shoulder1_part_material"/>
          <!-- Link shoulder2_subassembly -->
          <body name="shoulder2_subassembly" pos="-0.0258903 0.0281746 -0.0637558" quat="0.448098 -0.00589743 0.741862 -0.498813">
            <!-- Joint from shoulder1_subassembly to shoulder2_subassembly -->
            <joint axis="0 0 1" name="shoulder2_right" type="hinge"/>
            <inertial pos="0.0503222 -0.00802453 -0.0185814" mass="0.813928" fullinertia="0.000525696 0.00220185 0.00222619 0.000274135 0.000432213 -6.88388e-05"/>
            <!-- Part shoulder2_part -->
            <geom type="mesh" class="visual" pos="0.000468005 -7.46642e-05 0.0076" quat="8.3058e-16 1 -1.07679e-15 2.40491e-16" mesh="shoulder2_part" material="shoulder2_part_material"/>
            <!-- Part bearing_holder_upperbody_3 -->
            <geom type="mesh" class="visual" pos="-0.0301619 -0.0078876 -0.161645" quat="0.896808 0.0899086 -0.431027 0.0432121" mesh="bearing_holder_upperbody" material="bearing_holder_upperbody_material"/>
            <!-- Part rs00_5 -->
            <!-- Part robstrideo0_5 -->
            <geom type="mesh" class="visual" pos="0.672821 0.010962 -0.0204" quat="4.996e-16 -7.81623e-16 -0.707107 0.707107" mesh="robstrideo0" material="robstrideo0_material"/>
            <!-- Part bearing_holder_upperbody_4 -->
            <geom type="mesh" class="visual" pos="-0.0145093 -0.0293258 0.0548542" quat="0.552156 0.707107 0.432937 -0.0876886" mesh="bearing_holder_upperbody" material="bearing_holder_upperbody_material"/>
            <!-- Part robstrideo0_6 -->
            <geom type="mesh" class="visual" pos="0.526487 0.0981138 0.476889" quat="0.335337 0.274226 0.570564 -0.697714" mesh="robstrideo0" material="robstrideo0_material"/>
            <!-- Part rs00_6 -->
            <!-- Link shoulder3_subassembly -->
            <body name="shoulder3_subassembly" pos="0.10649 -0.0169749 -0.0361066" quat="0.585764 0.284507 -0.336041 -0.68045">
              <!-- Joint from shoulder2_subassembly to shoulder3_subassembly -->
              <joint axis="0 0 1" name="shoulder3_right" type="hinge"/>
              <inertial pos="-0.0110338 4.44904e-10 -0.0847765" mass="0.356129" fullinertia="0.000279042 0.000233518 0.000103338 -1.77807e-12 -2.6579e-05 -4.9388e-12"/>
              <!-- Part rs00_7 -->
              <!-- Part robstrideo0_7 -->
              <geom type="mesh" class="visual" pos="-0.025 -0.672821 -0.102555" quat="0.707107 1.63628e-15 2.10942e-15 0.707107" mesh="robstrideo0" material="robstrideo0_material"/>
              <!-- Part shoulder3_part -->
              <geom type="mesh" class="visual" pos="0 0 -0.091593" quat="0.5 0.5 0.5 -0.5" mesh="shoulder3_part" material="shoulder3_part_material"/>
              <!-- Link forarm_subassembly -->
              <body name="forarm_subassembly" pos="0.0264 -2.77556e-17 -0.091593" quat="0.5 -0.5 -0.5 0.5">
                <!-- Joint from shoulder3_subassembly to forarm_subassembly -->
                <joint axis="0 0 1" name="elbow_right" type="hinge"/>
                <inertial pos="0.11974 6.14939e-17 0.026489" mass="0.119991" fullinertia="2.5897e-05 0.000586836 0.000576186 -1.43221e-19 -7.3416e-06 -6.45599e-13"/>
                <!-- Part forarm_part -->
                <geom type="mesh" class="visual" pos="-5.55112e-17 5.55112e-17 0.027" quat="0.707107 0.707107 3.33067e-16 -1.01068e-16" mesh="forarm_part" material="forarm_part_material"/>
                <geom type="capsule" size="0.03 0.12" name="left_arm_collision" class="collision" pos="-5.55112e-17 5.55112e-17 0.027" quat="0.707107 0.707107 3.33067e-16 -1.01068e-16"/>
                <!-- Frame right_hand -->
                <site group="3" name="right_hand" pos="0.23 5.55112e-17 0.027" quat="0.707107 0.707107 2.22045e-16 -9.07618e-17"/>
              </body>
            </body>
          </body>
        </body>
        <!-- Link shoulder1_subassembly_2 -->
        <body name="shoulder1_subassembly_2" pos="-0.00401992 -0.10362 -0.230772" quat="0.218047 0.851171 0.176577 -0.443603">
          <!-- Joint from torso_subassembly_2 to shoulder1_subassembly_2 -->
          <joint axis="0 0 1" name="shoulder1_left" type="hinge"/>
          <inertial pos="-0.00416441 0.00450914 -0.0453884" mass="0.0533612" fullinertia="3.8204e-05 3.76594e-05 1.45394e-05 3.3665e-06 -4.64098e-06 4.9903e-06"/>
          <!-- Part shoulder1_part_2 -->
          <geom type="mesh" class="visual" pos="0.000329193 0.000172647 -0.0246" quat="1 1.57795e-14 5.21805e-15 1.89735e-19" mesh="shoulder1_part" material="shoulder1_part_material"/>
          <!-- Link shoulder2_subassembly_2 -->
          <body name="shoulder2_subassembly_2" pos="-0.0258903 0.0281746 -0.0637558" quat="0.669972 0.567825 0.47746 0.0272682">
            <!-- Joint from shoulder1_subassembly_2 to shoulder2_subassembly_2 -->
            <joint axis="0 0 1" name="shoulder2_left" type="hinge"/>
            <inertial pos="0.0503222 -0.00802453 -0.0185814" mass="0.813928" fullinertia="0.000525696 0.00220185 0.00222619 0.000274135 0.000432213 -6.88388e-05"/>
            <!-- Part shoulder2_part_2 -->
            <geom type="mesh" class="visual" pos="0.000468005 -7.46642e-05 0.0076" quat="5.85478e-18 -1 2.60477e-16 -4.9825e-17" mesh="shoulder2_part" material="shoulder2_part_material"/>
            <!-- Part bearing_holder_upperbody_5 -->
            <geom type="mesh" class="visual" pos="-0.0301619 -0.0078876 -0.161645" quat="0.896808 0.0899086 -0.431027 0.0432121" mesh="bearing_holder_upperbody" material="bearing_holder_upperbody_material"/>
            <!-- Part rs00_8 -->
            <!-- Part robstrideo0_8 -->
            <geom type="mesh" class="visual" pos="0.672821 0.010962 -0.0204" quat="5.55112e-16 -1.19386e-15 -0.707107 0.707107" mesh="robstrideo0" material="robstrideo0_material"/>
            <!-- Part bearing_holder_upperbody_6 -->
            <geom type="mesh" class="visual" pos="-0.0145093 -0.0293258 0.0548542" quat="0.552156 0.707107 0.432937 -0.0876886" mesh="bearing_holder_upperbody" material="bearing_holder_upperbody_material"/>
            <!-- Part robstrideo0_9 -->
            <geom type="mesh" class="visual" pos="0.526487 0.0981138 0.476889" quat="0.335337 0.274226 0.570564 -0.697714" mesh="robstrideo0" material="robstrideo0_material"/>
            <!-- Part rs00_9 -->
            <!-- Link shoulder3_subassembly_2 -->
            <body name="shoulder3_subassembly_2" pos="0.10649 -0.0169749 -0.0361066" quat="0.509799 -0.397169 -0.190063 0.739079">
              <!-- Joint from shoulder2_subassembly_2 to shoulder3_subassembly_2 -->
              <joint axis="0 0 1" name="shoulder3_left" type="hinge"/>
              <inertial pos="-0.0110338 4.44904e-10 -0.0847765" mass="0.356129" fullinertia="0.000279042 0.000233518 0.000103338 -1.77807e-12 -2.6579e-05 -4.9388e-12"/>
              <!-- Part rs00_10 -->
              <!-- Part robstrideo0_10 -->
              <geom type="mesh" class="visual" pos="-0.025 -0.672821 -0.102555" quat="0.707107 3.07846e-16 -8.88178e-16 0.707107" mesh="robstrideo0" material="robstrideo0_material"/>
              <!-- Part shoulder3_part_2 -->
              <geom type="mesh" class="visual" pos="0 -2.77556e-17 -0.091593" quat="0.5 0.5 0.5 -0.5" mesh="shoulder3_part" material="shoulder3_part_material"/>
              <!-- Link forarm_subassembly_2 -->
              <body name="forarm_subassembly_2" pos="0.0264 -2.77556e-17 -0.091593" quat="0.41491 0.572582 -0.41491 -0.572582">
                <!-- Joint from shoulder3_subassembly_2 to forarm_subassembly_2 -->
                <joint axis="0 0 1" name="elbow_left" type="hinge"/>
                <inertial pos="0.11974 -4.83429e-18 0.026489" mass="0.119991" fullinertia="2.5897e-05 0.000586836 0.000576186 1.92888e-20 -7.3416e-06 -6.45599e-13"/>
                <!-- Part forarm_part_2 -->
                <geom type="mesh" class="visual" pos="0 0 0.027" quat="0.707107 0.707107 1.11022e-16 -1.2663e-16" mesh="forarm_part" material="forarm_part_material"/>
                <geom type="capsule" size="0.03 0.12" name="right_arm_collision" class="collision" pos="0 0 0.027" quat="0.707107 0.707107 1.11022e-16 -1.2663e-16"/>
                <!-- Frame left_hand -->
                <site group="3" name="left_hand" pos="0.23 4.16334e-17 0.027" quat="0.707107 -0.707107 1.55431e-15 1.74024e-15"/>
              </body>
            </body>
          </body>
        </body>
      </body>
    </body>
  </worldbody>
  <asset>
    <mesh file="actuation_ankle.stl"/>
    <mesh file="bearing_15_21_4.stl"/>
    <mesh file="1_1_06_eb463_509_fl46blw10_48v_5n_m_de_2__fl46blw10_48v_5n_m_de.stl"/>
    <mesh file="femur_12.stl"/>
    <mesh file="robstrideo0.stl"/>
    <mesh file="1_1_02_eb901_558_1.stl"/>
    <mesh file="hipz22_sym.stl"/>
    <mesh file="1_1_06_eb463_507_fl46blw10_48v_5n_m_de_2__fl46blw10_48v_5n_m_de.stl"/>
    <mesh file="tibias22_sym.stl"/>
    <mesh file="shoulder1_part.stl"/>
    <mesh file="bearing_35_72_17.stl"/>
    <mesh file="knee_rod22.stl"/>
    <mesh file="hat_femur.stl"/>
    <mesh file="xt_30_2x2_f.stl"/>
    <mesh file="hipz22.stl"/>
    <mesh file="femur_12_sym.stl"/>
    <mesh file="0001755652_00mini_000_asm_1_asm_1_asm_00mini__20250103_a0001_asm_1_as_asm_1_1_30_gr_2202_asm_1_asm_1_1_30_gr_2202_asm_fl46blw10_48v_5n_m_de_2__fl46blw10_48v_5n_m_de.stl"/>
    <mesh file="bearing_5_16_5.stl"/>
    <mesh file="torso_pperbody_part.stl"/>
    <mesh file="1_1_06_eb903_538_1.stl"/>
    <mesh file="1_1_31_qt_942_1.stl"/>
    <mesh file="knee_rod12_sym.stl"/>
    <mesh file="robstride02.stl"/>
    <mesh file="07534_05x40_catpart.stl"/>
    <mesh file="07534_05x20_catpart.stl"/>
    <mesh file="tibias12.stl"/>
    <mesh file="0001755650_00mini_000_asm_1_asm_1_asm_00mini__20250103_a0001_asm_1_as_asm_1_1_30_gr_2202_asm_1_asm_1_1_30_gr_2202_asm_fl46blw10_48v_5n_m_de_2__fl46blw10_48v_5n_m_de.stl"/>
    <mesh file="bearing_holder_upperbody.stl"/>
    <mesh file="femur_22.stl"/>
    <mesh file="part_3.stl"/>
    <mesh file="hipz12.stl"/>
    <mesh file="torso22.stl"/>
    <mesh file="knee_actuation.stl"/>
    <mesh file="hex_thin_nut_grade_a___b_m4x0_7__a8228d9ce5dcc05f24da0a2f74d882f3.stl"/>
    <mesh file="1_1_02_eb461_502_fl46blw10_48v_5n_m_de_2__fl46blw10_48v_5n_m_de.stl"/>
    <mesh file="27628_01_050_catpart.stl"/>
    <mesh file="shoulder3_part.stl"/>
    <mesh file="forarm_part.stl"/>
    <mesh file="6706__300001_1_1_00mini_000_asm_1_asm_1_asm_00mini__20250103_a0001_asm_1_as_asm_1_1_30_gr_2202_asm_1_asm_1_1_30_gr_2202_asm_fl46blw10_48v_5n_m_de_2__fl46blw10_48v_5n_m_de.stl"/>
    <mesh file="spacer_ujoint.stl"/>
    <mesh file="ujoint.stl"/>
    <mesh file="hipxy.stl"/>
    <mesh file="knee_rod12.stl"/>
    <mesh file="tibias22.stl"/>
    <mesh file="hat_big.stl"/>
    <mesh file="foot.stl"/>
    <mesh file="shoulder2_part.stl"/>
    <mesh file="hipz12_sym.stl"/>
    <mesh file="hat_small.stl"/>
    <mesh file="tibias12_sym.stl"/>
    <mesh file="torso12.stl"/>
    <mesh file="1_1_06_eb903_537_af0_1.stl"/>
    <mesh file="femur_22_sym.stl"/>
    <mesh file="hipxy_sym.stl"/>
    <mesh file="rmdx43.stl"/>
    <mesh file="0001755652_1_1_30_gr_2202_asm_1_asm_1_1_30_gr_2202_asm_fl46blw10_48v_5n_m_de_2__fl46blw10_48v_5n_m_de.stl"/>
    <mesh file="knee_rod22_sym.stl"/>
    <mesh file="1_1_31_eb463_510_fl46blw10_48v_5n_m_de_2__fl46blw10_48v_5n_m_de.stl"/>
    <mesh file="robstrideo3.stl"/>
    <material name="torso22_material" rgba="1 0 0 1"/>
    <material name="bearing_35_72_17_material" rgba="0.768627 0.886275 0.952941 1"/>
    <material name="robstrideo0_material" rgba="0.301961 0.301961 0.301961 1"/>
    <material name="torso12_material" rgba="1 0 0 1"/>
    <material name="xt_30_2x2_f_material" rgba="0.917647 0.917647 0.917647 1"/>
    <material name="hipz12_material" rgba="1 0 0 1"/>
    <material name="robstride02_material" rgba="0.301961 0.301961 0.301961 1"/>
    <material name="hipz22_material" rgba="1 0 0 1"/>
    <material name="hipxy_material" rgba="1 0 0 1"/>
    <material name="knee_rod22_material" rgba="0.917647 0.917647 0.917647 1"/>
    <material name="bearing_15_21_4_material" rgba="0.647059 0.647059 0.647059 1"/>
    <material name="robstrideo3_material" rgba="0.301961 0.301961 0.301961 1"/>
    <material name="knee_rod12_material" rgba="0.917647 0.917647 0.917647 1"/>
    <material name="bearing_5_16_5_material" rgba="0.917647 0.917647 0.917647 1"/>
    <material name="knee_actuation_material" rgba="0.917647 0.917647 0.917647 1"/>
    <material name="femur_22_material" rgba="1 0 0 1"/>
    <material name="femur_12_material" rgba="1 0 0 1"/>
    <material name="hat_femur_material" rgba="1 0 0 1"/>
    <material name="part_3_material" rgba="1 0 0 1"/>
    <material name="1_1_31_qt_942_1_material" rgba="0.768627 0.886275 0.952941 1"/>
    <material name="1_1_06_eb903_538_1_material" rgba="0.498039 0.498039 0.498039 1"/>
    <material name="1_1_06_eb903_537_af0_1_material" rgba="0.768627 0.886275 0.952941 1"/>
    <material name="1_1_02_eb901_558_1_material" rgba="0.917647 0.917647 0.917647 1"/>
    <material name="rmdx43_material" rgba="0.301961 0.301961 0.301961 1"/>
    <material name="tibias22_material" rgba="1 0 0 1"/>
    <material name="27628_01_050_catpart_material" rgba="0.690196 0.690196 0.690196 1"/>
    <material name="hex_thin_nut_grade_a___b_m4x0_7__a8228d9ce5dcc05f24da0a2f74d882f3_material" rgba="0.603922 0.647059 0.686275 1"/>
    <material name="07534_05x40_catpart_material" rgba="0.690196 0.690196 0.690196 1"/>
    <material name="07534_05x20_catpart_material" rgba="0.690196 0.690196 0.690196 1"/>
    <material name="actuation_ankle_material" rgba="0.917647 0.917647 0.917647 1"/>
    <material name="hat_big_material" rgba="1 0 0 1"/>
    <material name="tibias12_material" rgba="1 0 0 1"/>
    <material name="1_1_31_eb463_510_fl46blw10_48v_5n_m_de_2__fl46blw10_48v_5n_m_de_material" rgba="1 1 1 1"/>
    <material name="1_1_02_eb461_502_fl46blw10_48v_5n_m_de_2__fl46blw10_48v_5n_m_de_material" rgba="1 1 1 1"/>
    <material name="1_1_06_eb463_509_fl46blw10_48v_5n_m_de_2__fl46blw10_48v_5n_m_de_material" rgba="1 1 1 1"/>
    <material name="1_1_06_eb463_507_fl46blw10_48v_5n_m_de_2__fl46blw10_48v_5n_m_de_material" rgba="1 1 1 1"/>
    <material name="0001755652_1_1_30_gr_2202_asm_1_asm_1_1_30_gr_2202_asm_fl46blw10_48v_5n_m_de_2__fl46blw10_48v_5n_m_de_material" rgba="1 1 1 1"/>
    <material name="0001755652_00mini_000_asm_1_asm_1_asm_00mini__20250103_a0001_asm_1_as_asm_1_1_30_gr_2202_asm_1_asm_1_1_30_gr_2202_asm_fl46blw10_48v_5n_m_de_2__fl46blw10_48v_5n_m_de_material" rgba="1 1 1 1"/>
    <material name="6706__300001_1_1_00mini_000_asm_1_asm_1_asm_00mini__20250103_a0001_asm_1_as_asm_1_1_30_gr_2202_asm_1_asm_1_1_30_gr_2202_asm_fl46blw10_48v_5n_m_de_2__fl46blw10_48v_5n_m_de_material" rgba="1 1 1 1"/>
    <material name="0001755650_00mini_000_asm_1_asm_1_asm_00mini__20250103_a0001_asm_1_as_asm_1_1_30_gr_2202_asm_1_asm_1_1_30_gr_2202_asm_fl46blw10_48v_5n_m_de_2__fl46blw10_48v_5n_m_de_material" rgba="1 1 1 1"/>
    <material name="ujoint_material" rgba="1 0 0 1"/>
    <material name="spacer_ujoint_material" rgba="0.917647 0.917647 0.917647 1"/>
    <material name="hat_small_material" rgba="1 0 0 1"/>
    <material name="foot_material" rgba="0.301961 0.301961 0.301961 1"/>
    <material name="hipz22_sym_material" rgba="1 0 0 1"/>
    <material name="hipz12_sym_material" rgba="1 0 0 1"/>
    <material name="hipxy_sym_material" rgba="1 0 0 1"/>
    <material name="knee_rod22_sym_material" rgba="0.917647 0.917647 0.917647 1"/>
    <material name="femur_12_sym_material" rgba="1 0 0 1"/>
    <material name="femur_22_sym_material" rgba="1 0 0 1"/>
    <material name="knee_rod12_sym_material" rgba="0.917647 0.917647 0.917647 1"/>
    <material name="tibias12_sym_material" rgba="1 0 0 1"/>
    <material name="tibias22_sym_material" rgba="1 0 0 1"/>
    <material name="torso_pperbody_part_material" rgba="0.301961 0.301961 0.301961 1"/>
    <material name="bearing_holder_upperbody_material" rgba="1 0 0 1"/>
    <material name="shoulder1_part_material" rgba="0.917647 0.917647 0.917647 1"/>
    <material name="shoulder2_part_material" rgba="1 0 0 1"/>
    <material name="shoulder3_part_material" rgba="1 0 0 1"/>
    <material name="forarm_part_material" rgba="0.917647 0.917647 0.917647 1"/>
  </asset>
  <equality/>

    <sensor>
    <gyro name="imu_ang_vel" site="imu"/>
    <velocimeter name="imu_lin_vel" site="imu"/>
    <accelerometer name="imu_lin_acc" site="imu"/>
    <subtreeangmom name="root_angmom" body="torso_subassembly"/>
    </sensor>
  
  

</mujoco>
